Workbook

Sheet Matriz_Activos
A1: Matriz consolidada de activos por área y mantenimiento
A3: Cruce exacto de placas contra activos.xlsx. No se aplicaron correcciones automáticas a placas no coincidentes.
A4: Activo | B4: Nombre | C4: Descripción | D4: Área | E4: Dependencia | F4: Fecha de Último mantenimiento | G4: Orden Área | H4: Estado mantenimiento | I4: Aporta al Plan de Mejoramiento | J4: NUMERO_PERIODOS_VIDA_UTIL | K4: CANTIDAD_PERIODOS_DEPRECIADOS | L4: FECHA_INICIO_DEPRECIACION | M4: DEPRECIADO
A5: U15201000681 | B5: COMPACTADOR AUTOMÁTICO PARA ENSAYOS CBR Y PROCTOR | C5: EQUIPO LABORATORIO - COMPACTADOR AUTOMATICO PARA PROCTOR | D5: Académica | E5: CIPAV | G5: =IFERROR(VLOOKUP(D5,Listas!$A$2:$B$20,2,FALSE()),999) -> 1 | H5: =IF(F5="","Sin fecha",IF(TODAY()-F5>180,"Revisar",IF(TODAY()-F5>90,"Próximo","Vigente"))) -> Sin fecha | J5: 120 | K5: 8 | L5: 46023 | M5: N
A6: U15201000680 | B6: COMPACTADOR MARSHALL AUTOMÁTICO | C6: EQUIPO LABORATORIO - COMPACTADOR AUTOMATICO MARSHALL PARA MUESTRAS ASFALTICAS | D6: Académica | E6: CIPAV | G6: =IFERROR(VLOOKUP(D6,Listas!$A$2:$B$20,2,FALSE()),999) -> 1 | H6: =IF(F6="","Sin fecha",IF(TODAY()-F6>180,"Revisar",IF(TODAY()-F6>90,"Próximo","Vigente"))) -> Sin fecha | J6: 120 | K6: 8 | L6: 46023 | M6: N
A7: U15201000678 | B7: EQUIPO DE ENSAYO DE PLACA DE CARGA | C7: EQUIPO LABORATORIO - VIGAS BENKELMAN DOBLE PARA MEDIR EL RADIO CORVATURA DEL ASFAL | D7: Académica | E7: CIPAV | G7: =IFERROR(VLOOKUP(D7,Listas!$A$2:$B$20,2,FALSE()),999) -> 1 | H7: =IF(F7="","Sin fecha",IF(TODAY()-F7>180,"Revisar",IF(TODAY()-F7>90,"Próximo","Vigente"))) -> Sin fecha | J7: 120 | K7: 8 | L7: 46023 | M7: N
A8: U15201000677 | B8: Manual de Operación: Punto de Reblandecimiento del Asfalto | C8: EQUIPO LABORATORIO - PROBADOR AUTOMATICO DE ANILLO Y BOLA O PUNTO DE ABLANDAMIENTO. | D8: Académica | E8: CIPAV | G8: =IFERROR(VLOOKUP(D8,Listas!$A$2:$B$20,2,FALSE()),999) -> 1 | H8: =IF(F8="","Sin fecha",IF(TODAY()-F8>180,"Revisar",IF(TODAY()-F8>90,"Próximo","Vigente"))) -> Sin fecha | J8: 120 | K8: 8 | L8: 46023 | M8: N
A9: U15201000668 | B9: PERMEÁMETRO MULTIPROPÓSITO PARA ENSAYOS DE PERMEABILIDAD EN SUELOS | C9: EQUIPO LABORATORIO - CONSTRUCCIÓN, ENSAMBLAJE Y SUMINISTRO DE UN DISPOSITIVO PERMEÁMETRO MULTIPROPÓSITO, SEGÚN DISEÑO ESCOGIDO POR EL CLIENTE REF: PER001 | D9: Académica | E9: CIPAV | G9: =IFERROR(VLOOKUP(D9,Listas!$A$2:$B$20,2,FALSE()),999) -> 1 | H9: =IF(F9="","Sin fecha",IF(TODAY()-F9>180,"Revisar",IF(TODAY()-F9>90,"Próximo","Vigente"))) -> Sin fecha | J9: 120 | K9: 8 | L9: 46023 | M9: N
A10: U15201000010 | B10: VISCOSÍMETRO DIGITAL BROOKFIELD PARA ENSAYOS DE VISCOSIDAD EN CEMENTOS ASFÁLTICOS | C10: EQUIPO LABORATORIO PENETRO-METRO . PROVEEDOR:890704382 UNIVERSIDAD DE IBAGUE | D10: Académica | E10: CIPAV | G10: =IFERROR(VLOOKUP(D10,Listas!$A$2:$B$20,2,FALSE()),999) -> 1 | H10: =IF(F10="","Sin fecha",IF(TODAY()-F10>180,"Revisar",IF(TODAY()-F10>90,"Próximo","Vigente"))) -> Sin fecha | J10: 120 | K10: 120 | L10: 41090 | M10: S
A11: U15201000407 | B11: Ac voltage/current data loger | C11: EQUIPO LABORATORIO ANALIZADOR DE CORRIENTE EXTECH. PROVEEDOR:93411261 HERNAN DARIO QUIÑONES | D11: Académica | E11: Energías renovables | G11: =IFERROR(VLOOKUP(D11,Listas!$A$2:$B$20,2,FALSE()),999) -> 1 | H11: =IF(F11="","Sin fecha",IF(TODAY()-F11>180,"Revisar",IF(TODAY()-F11>90,"Próximo","Vigente"))) -> Sin fecha | J11: 1 | K11: 1 | L11: 42886 | M11: S
A12: U15201000408 | B12: Ac voltage/current data loger | C12: EQUIPO LABORATORIO ANALIZADOR DE CORRIENTE EXTECH. PROVEEDOR:890704382 UNIVERSIDAD DE IBAGUE | D12: Académica | E12: Energías renovables | G12: =IFERROR(VLOOKUP(D12,Listas!$A$2:$B$20,2,FALSE()),999) -> 1 | H12: =IF(F12="","Sin fecha",IF(TODAY()-F12>180,"Revisar",IF(TODAY()-F12>90,"Próximo","Vigente"))) -> Sin fecha | J12: 1 | K12: 1 | L12: 42886 | M12: S
A13: U15201000409 | B13: Ac voltage/current data loger | C13: EQUIPO LABORATORIO ANALIZADOR DE CORRIENTE EXTECH. PROVEEDOR:890704382 UNIVERSIDAD DE IBAGUE | D13: Académica | E13: Energías renovables | G13: =IFERROR(VLOOKUP(D13,Listas!$A$2:$B$20,2,FALSE()),999) -> 1 | H13: =IF(F13="","Sin fecha",IF(TODAY()-F13>180,"Revisar",IF(TODAY()-F13>90,"Próximo","Vigente"))) -> Sin fecha | J13: 1 | K13: 1 | L13: 42886 | M13: S
A14: U15201000413 | B14: Ac voltage/current data loger | C14: EQUIPO LABORATORIO ANALIZADOR DE CORRIENTE MARCA ERASMUS MODELO EDL - 10. PROVEEDOR:890704382 UNIVERSIDAD DE IBAGUE | D14: Académica | E14: Energías renovables | G14: =IFERROR(VLOOKUP(D14,Listas!$A$2:$B$20,2,FALSE()),999) -> 1 | H14: =IF(F14="","Sin fecha",IF(TODAY()-F14>180,"Revisar",IF(TODAY()-F14>90,"Próximo","Vigente"))) -> Sin fecha | J14: 1 | K14: 1 | L14: 42886 | M14: S
A15: U15201000414 | B15: Ac voltage/current data loger | C15: EQUIPO LABORATORIO ANALIZADOR DE CORRIENTE EXTECH. PROVEEDOR:890704382 UNIVERSIDAD DE IBAGUE | D15: Académica | E15: Energías renovables | G15: =IFERROR(VLOOKUP(D15,Listas!$A$2:$B$20,2,FALSE()),999) -> 1 | H15: =IF(F15="","Sin fecha",IF(TODAY()-F15>180,"Revisar",IF(TODAY()-F15>90,"Próximo","Vigente"))) -> Sin fecha | J15: 1 | K15: 1 | L15: 42886 | M15: S
A16: U15201000415 | B16: Ac voltage/current data loger | C16: EQUIPO LABORATORIO ANALIZADOR DE CORRIENTE EXTECH. PROVEEDOR:890704382 UNIVERSIDAD DE IBAGUE | D16: Académica | E16: Energías renovables | G16: =IFERROR(VLOOKUP(D16,Listas!$A$2:$B$20,2,FALSE()),999) -> 1 | H16: =IF(F16="","Sin fecha",IF(TODAY()-F16>180,"Revisar",IF(TODAY()-F16>90,"Próximo","Vigente"))) -> Sin fecha | J16: 1 | K16: 1 | L16: 42886 | M16: S
... A43: U15201001163 | B43: BALANZA ANALITICA | C43: BALANZA - BALANZA DIGITAL: BALANZA ANALITICA, TUNING FORK SENSOR, CALIBRACION EXTERNA CAP 220 G LEG 0.0001 G REF HT224 MARCA VIBRA | D43: Académica | E43: Lab. de Diseño de Sistemas Mecanicos | G43: =IFERROR(VLOOKUP(D43,Listas!$A$2:$B$20,2,FALSE()),999) -> 1 | H43: =IF(F43="","Sin fecha",IF(TODAY()-F43>180,"Revisar",IF(TODAY()-F43>90,"Próximo","Vigente"))) -> Sin fecha | J43: 120 | K43: 60 | L43: 44440 | M43: N
A44: U15200500130 | B44: BANCO DE ENSAYOS DE EXTREMA PRESION | C44: MAQUINARIA Y EQUIPO BANCO PARA ENSAYOS DE EXTREMA PRESION EN ACEITE LUBRICANTES . PROVEEDOR:890704382 UNIVERSIDAD DE IBAGUE | D44: Académica | E44: Lab. de Diseño de Sistemas Mecanicos | F44: 46244 | G44: =IFERROR(VLOOKUP(D44,Listas!$A$2:$B$20,2,FALSE()),999) -> 1 | H44: =IF(F44="","Sin fecha",IF(TODAY()-F44>180,"Revisar",IF(TODAY()-F44>90,"Próximo","Vigente"))) -> Vigente | J44: 120 | K44: 120 | L44: 41090 | M44: S
A45: U15200500133 | B45: BANCO DE VIBRACIONES | C45: MAQUINARIA Y EQUIPO BANCO PARA ENSAYO PARA VIBRACIONES . PROVEEDOR:890704382 UNIVERSIDAD DE IBAGUE | D45: Académica | E45: Lab. de Diseño de Sistemas Mecanicos | G45: =IFERROR(VLOOKUP(D45,Listas!$A$2:$B$20,2,FALSE()),999) -> 1 | H45: =IF(F45="","Sin fecha",IF(TODAY()-F45>180,"Revisar",IF(TODAY()-F45>90,"Próximo","Vigente"))) -> Sin fecha | J45: 120 | K45: 120 | L45: 41090 | M45: S
A46: U15200500131 | B46: BANCO PIN ON DISC | C46: MAQUINARIA Y EQUIPO PIN ON DISC. PROVEEDOR:890704382 UNIVERSIDAD DE IBAGUE | D46: Académica | E46: Lab. de Diseño de Sistemas Mecanicos | G46: =IFERROR(VLOOKUP(D46,Listas!$A$2:$B$20,2,FALSE()),999) -> 1 | H46: =IF(F46="","Sin fecha",IF(TODAY()-F46>180,"Revisar",IF(TODAY()-F46>90,"Próximo","Vigente"))) -> Sin fecha | J46: 120 | K46: 120 | L46: 41090 | M46: S
A47: U15201001146 | B47: CAMARA TERMOGRAFICA | C47: CAMARA TERMOGRAFICA - W8060 | D47: Académica | E47: Lab. de Diseño de Sistemas Mecanicos | G47: =IFERROR(VLOOKUP(D47,Listas!$A$2:$B$20,2,FALSE()),999) -> 1 | H47: =IF(F47="","Sin fecha",IF(TODAY()-F47>180,"Revisar",IF(TODAY()-F47>90,"Próximo","Vigente"))) -> Sin fecha | J47: 120 | K47: 85 | L47: 43706 | M47: N
A48: U15200503445 | B48: DESHUMIDIFICADOR | C48: DESHUMIDIFICADOR ELECTROLUX MODELO FFAD2234W1 115 VOLTS SERVICE MODEL FFAD2234W10 | D48: Académica | E48: Lab. de Diseño de Sistemas Mecanicos | G48: =IFERROR(VLOOKUP(D48,Listas!$A$2:$B$20,2,FALSE()),999) -> 1 | H48: =IF(F48="","Sin fecha",IF(TODAY()-F48>180,"Revisar",IF(TODAY()-F48>90,"Próximo","Vigente"))) -> Sin fecha | J48: 120 | K48: 20 | L48: 45658 | M48: N
A49: U15201001225 | B49: EQUIPO DE VIBRACIONES | C49: EQUIPO DE VIBRACIONES ERBESSD | D49: Académica | E49: Lab. de Diseño de Sistemas Mecanicos | G49: =IFERROR(VLOOKUP(D49,Listas!$A$2:$B$20,2,FALSE()),999) -> 1 | H49: =IF(F49="","Sin fecha",IF(TODAY()-F49>180,"Revisar",IF(TODAY()-F49>90,"Próximo","Vigente"))) -> Sin fecha | J49: 1 | K49: 1 | L49: 44986 | M49: S
A50: U15201000162 | B50: LAMPARA ESTROBOSCOPICA | C50: EQUIPO LABORATORIO LAMPARA ESTREBOSTROPICA MARCA SKF MODELO TKRS20. PROVEEDOR:890704382 UNIVERSIDAD DE IBAGUE | D50: Académica | E50: Lab. de Diseño de Sistemas Mecanicos | G50: =IFERROR(VLOOKUP(D50,Listas!$A$2:$B$20,2,FALSE()),999) -> 1 | H50: =IF(F50="","Sin fecha",IF(TODAY()-F50>180,"Revisar",IF(TODAY()-F50>90,"Próximo","Vigente"))) -> Sin fecha | J50: 120 | K50: 120 | L50: 41090 | M50: S
A51: U15200500132 | B51: MOTOR BANCO DE TRANSMISION | C51: MAQUINARIA Y EQUIPO MOTOR - BANCO PARA ENSAYOS DE TRANSMISION O ENLASES FLEXIBLES . PROVEEDOR:890704382 UNIVERSIDAD DE IBAGUE | D51: Académica | E51: Lab. de Diseño de Sistemas Mecanicos | G51: =IFERROR(VLOOKUP(D51,Listas!$A$2:$B$20,2,FALSE()),999) -> 1 | H51: =IF(F51="","Sin fecha",IF(TODAY()-F51>180,"Revisar",IF(TODAY()-F51>90,"Próximo","Vigente"))) -> Sin fecha | J51: 120 | K51: 120 | L51: 41090 | M51: S
A52: U15280502039 | B52: PC WORKSTATION | C52: ESTACION DE TRABAJO - TORRE DELL PRECISION 5820 XCTO BASE - 1028387277809 PROCESADOR INTEL® XEON® W-2145 3.7GHZ, 4.5GHZ TURBO, 8C, 11M CACHE, HT, (140W) DDR4-2666 WINDOWS® 10 PRO PARA WORKSTATION (4 NÚCLEOS PLUS) ESPAÑOL PRUEBA DE 30 DÍAS DE MICROSOFT OFFICE DUAL NVIDIA® QUADRO®P1000, 4GB, 4 MDP (5820T) MOD; DIMM; 64 G; 4 X 16 G; 2667; RDIM UNIDAD DE ESTADO SÓLIDO CLASE 20 SATA DE 512 GB Y 2,5" DISCO DURO SATA DE 3,5 GB - 2 TB DE 7200 RPM UNIDAD ÓPTICA 8X DELGADA (DVD +/- RW) TECLADO CON CABLE DELL KB216, ESPAÑOL MOUSE CABLEADO DELL MS116; NEGRO 3 AÑOS DE PROSUPPORT CON SERVICIO EN SITIO AL SIGUIENTE DÍA LABORABLE DELL 24 MONITOR | P2417H | D52: Académica | E52: Lab. de Diseño de Sistemas Mecanicos | G52: =IFERROR(VLOOKUP(D52,Listas!$A$2:$B$20,2,FALSE()),999) -> 1 | H52: =IF(F52="","Sin fecha",IF(TODAY()-F52>180,"Revisar",IF(TODAY()-F52>90,"Próximo","Vigente"))) -> Sin fecha | J52: 60 | K52: 60 | L52: 43425 | M52: S
A53: U15200500518 | B53: PINZA VOLTIAMPERIMETRICA | C53: MAQUINARIA Y EQUIPO PINZAS VOLTIAMPERIMETRICA. PROVEEDOR:890704382 UNIVERSIDAD DE IBAGUE | D53: Académica | E53: Lab. de Diseño de Sistemas Mecanicos | G53: =IFERROR(VLOOKUP(D53,Listas!$A$2:$B$20,2,FALSE()),999) -> 1 | H53: =IF(F53="","Sin fecha",IF(TODAY()-F53>180,"Revisar",IF(TODAY()-F53>90,"Próximo","Vigente"))) -> Sin fecha | J53: 120 | K53: 120 | L53: 41090 | M53: S
A54: U15200500519 | B54: PINZA VOLTIAMPERIMETRICA | C54: MAQUINARIA Y EQUIPO PINZAS VOLTIAMPERIMETRICA. PROVEEDOR:890704382 UNIVERSIDAD DE IBAGUE | D54: Académica | E54: Lab. de Diseño de Sistemas Mecanicos | G54: =IFERROR(VLOOKUP(D54,Listas!$A$2:$B$20,2,FALSE()),999) -> 1 | H54: =IF(F54="","Sin fecha",IF(TODAY()-F54>180,"Revisar",IF(TODAY()-F54>90,"Próximo","Vigente"))) -> Sin fecha | J54: 120 | K54: 120 | L54: 41090 | M54: S
A55: U15201000070 | B55: PROTOTIPO CNC | C55: EQUIPO LABORATORIO PROTOTIPO DE MAQUINA CNC. PROVEEDOR:890704382 UNIVERSIDAD DE IBAGUE | D55: Académica | E55: Lab. de Diseño de Sistemas Mecanicos | G55: =IFERROR(VLOOKUP(D55,Listas!$A$2:$B$20,2,FALSE()),999) -> 1 | H55: =IF(F55="","Sin fecha",IF(TODAY()-F55>180,"Revisar",IF(TODAY()-F55>90,"Próximo","Vigente"))) -> Sin fecha | J55: 120 | K55: 120 | L55: 41090 | M55: S
A56: U15201001074 | B56: RUGOSIMETRO | C56: RUGOSIMETRO - TIME 3221 CON CARACTERÍSTICAS DE MEDICIÓN MULTIPARAMETRICA: RA, RP, RV, RT, RZ, RQ, RSK, RKU, RC, RPC, RSM, RMR (C), TP, RMR, RPM, RZ1MAX, RZJIS, RMAX, HTP, R¿C ,, R¿Q , R¿A, PA, PP, PV, PT, PZ, PQ, PSK, PKU, PC, PSM, PMR (C), PMR, PZ1MAX, PZJIS, P¿C, P¿Q RK, RPK, RVK, MR1, MR2, A1, A2 ; PASTILLA DE INDUCTANCIA DE ALTA PRECISIÓN MÉTODOS DE FILTRADO DE 2RC, GAUSS COMPATIBLE CON CUATRO ESTÁNDARES DE ISO1997, ANSI Y JIS2001. INCLUYE SOFTWARE NUESTRO TIME3221 SE PUEDE CONECTAR CON EL SOFTWARE, EN EL QUE PUEDE TRANSFERIR TODOS LOS DATOS A LA PC, INCLUIDAS LAS ONDAS | D56: Académica | E56: Lab. de Diseño de Sistemas Mecanicos | G56: =IFERROR(VLOOKUP(D56,Listas!$A$2:$B$20,2,FALSE()),999) -> 1 | H56: =IF(F56="","Sin fecha",IF(TODAY()-F56>180,"Revisar",IF(TODAY()-F56>90,"Próximo","Vigente"))) -> Sin fecha | J56: 120 | K56: 93 | L56: 43457 | M56: N
... A79: U15200503414 | B79: VIDEOBEAM | C79: VIDEOPROYECTOR LS610WH-4,0 LS610WH-4,000 ANSI LUMENS IEWSONIC WXGA LED PROJECTOR 4,000 ANSI UMENS WXGA LED USINESS/EDUCATION PROJECTOR TECNOLOGÍA LED DE 3ª GENERACIÓN PARA UNA MAYOR SOSTENIBILIDAD SIN MANTENIMIENTO: 60.000 HORAS DE VIDA ÚTIL DE LA FUENTE LUMINOSA Y MENOR CONSUMO DE ENERGÍA 4.000 ANSI LÚMENES PARA IMÁGENES BRILLANTES EN CUALQUIER ENTORNO FACILIDAD DE USO: ON/OFF INSTANTÁNEO KEYSTONE H/V Y CONTROL LAN AMPLIA GAMA CROMÁTICA PARA PRESENTACIONES DE ALTA CALIDAD | D79: Académica | E79: Lab. de Diseño Mecatronico | G79: =IFERROR(VLOOKUP(D79,Listas!$A$2:$B$20,2,FALSE()),999) -> 1 | H79: =IF(F79="","Sin fecha",IF(TODAY()-F79>180,"Revisar",IF(TODAY()-F79>90,"Próximo","Vigente"))) -> Sin fecha | J79: 120 | K79: 27 | L79: 45444 | M79: N
A80: U15200500954 | B80: FUENTE DE PODER | C80: MAQUINARIA Y EQUIPO FUENTE DE PODER MARCA BECAP MODELO 1652. PROVEEDOR:890704382 UNIVERSIDAD DE IBAGUE | D80: Académica | E80: Lab. Electromedicina L4 | F80: 45992 | G80: =IFERROR(VLOOKUP(D80,Listas!$A$2:$B$20,2,FALSE()),999) -> 1 | H80: =IF(F80="","Sin fecha",IF(TODAY()-F80>180,"Revisar",IF(TODAY()-F80>90,"Próximo","Vigente"))) -> Revisar | J80: 120 | K80: 120 | L80: 41090 | M80: S
A81: U15200500955 | B81: FUENTE DE PODER | C81: MAQUINARIA Y EQUIPO FUENTE DE PODER MARCA BECAP MODELO 1652. PROVEEDOR:890704382 UNIVERSIDAD DE IBAGUE | D81: Académica | E81: Lab. Electromedicina L4 | F81: 45992 | G81: =IFERROR(VLOOKUP(D81,Listas!$A$2:$B$20,2,FALSE()),999) -> 1 | H81: =IF(F81="","Sin fecha",IF(TODAY()-F81>180,"Revisar",IF(TODAY()-F81>90,"Próximo","Vigente"))) -> Revisar | J81: 120 | K81: 120 | L81: 41090 | M81: S
A82: U15200500956 | B82: FUENTE DE PODER | C82: MAQUINARIA Y EQUIPO FUENTE DE PODER MARCA BECAP MODELO 1652. PROVEEDOR:890704382 UNIVERSIDAD DE IBAGUE | D82: Académica | E82: Lab. Electromedicina L4 | F82: 45992 | G82: =IFERROR(VLOOKUP(D82,Listas!$A$2:$B$20,2,FALSE()),999) -> 1 | H82: =IF(F82="","Sin fecha",IF(TODAY()-F82>180,"Revisar",IF(TODAY()-F82>90,"Próximo","Vigente"))) -> Revisar | J82: 120 | K82: 120 | L82: 41090 | M82: S
A83: U15200500957 | B83: FUENTE DE PODER | C83: MAQUINARIA Y EQUIPO FUENTE DE PODER MARCA BECAP MODELO 1652. PROVEEDOR:890704382 UNIVERSIDAD DE IBAGUE | D83: Académica | E83: Lab. Electromedicina L4 | F83: 45992 | G83: =IFERROR(VLOOKUP(D83,Listas!$A$2:$B$20,2,FALSE()),999) -> 1 | H83: =IF(F83="","Sin fecha",IF(TODAY()-F83>180,"Revisar",IF(TODAY()-F83>90,"Próximo","Vigente"))) -> Revisar | J83: 120 | K83: 120 | L83: 41090 | M83: S
A84: U15200500958 | B84: FUENTE DE PODER | C84: MAQUINARIA Y EQUIPO FUENTE DE PODER MARCA BECAP MODELO 1652. PROVEEDOR:890704382 UNIVERSIDAD DE IBAGUE | D84: Académica | E84: Lab. Electromedicina L4 | F84: 45992 | G84: =IFERROR(VLOOKUP(D84,Listas!$A$2:$B$20,2,FALSE()),999) -> 1 | H84: =IF(F84="","Sin fecha",IF(TODAY()-F84>180,"Revisar",IF(TODAY()-F84>90,"Próximo","Vigente"))) -> Revisar | J84: 120 | K84: 120 | L84: 41090 | M84: S
A85: U15200501124 | B85: GENERADOR DE RF | C85: MAQUINARIA Y EQUIPO GENERADOR DE SEÑAL MARCA HP MODELO 8647A . PROVEEDOR:890704382 UNIVERSIDAD DE IBAGUE | D85: Académica | E85: Lab. Electromedicina L4 | F85: 45809 | G85: =IFERROR(VLOOKUP(D85,Listas!$A$2:$B$20,2,FALSE()),999) -> 1 | H85: =IF(F85="","Sin fecha",IF(TODAY()-F85>180,"Revisar",IF(TODAY()-F85>90,"Próximo","Vigente"))) -> Revisar | J85: 120 | K85: 120 | L85: 41090 | M85: S
A86: U15200501285 | B86: POWERLAB | C86: MAQUINARIA Y EQUIPO POWER LAB MARCA ADINTRUMENTS MODELO 15T. PROVEEDOR:890704382 UNIVERSIDAD DE IBAGUE | D86: Académica | E86: Lab. Electromedicina L4 | F86: 45809 | G86: =IFERROR(VLOOKUP(D86,Listas!$A$2:$B$20,2,FALSE()),999) -> 1 | H86: =IF(F86="","Sin fecha",IF(TODAY()-F86>180,"Revisar",IF(TODAY()-F86>90,"Próximo","Vigente"))) -> Revisar | J86: 120 | K86: 120 | L86: 41090 | M86: S
A87: U15200501286 | B87: POWERLAB | C87: MAQUINARIA Y EQUIPO POWER LAB MARCA ADINTRUMENTS MODELO 4856. PROVEEDOR:890704382 UNIVERSIDAD DE IBAGUE | D87: Académica | E87: Lab. Electromedicina L4 | F87: 45809 | G87: =IFERROR(VLOOKUP(D87,Listas!$A$2:$B$20,2,FALSE()),999) -> 1 | H87: =IF(F87="","Sin fecha",IF(TODAY()-F87>180,"Revisar",IF(TODAY()-F87>90,"Próximo","Vigente"))) -> Revisar | J87: 120 | K87: 120 | L87: 41090 | M87: S
A88: U15201000820 | B88: POWERLAB | C88: EQUIPO LABORATORIO - POWERLAB 15T REF ML4818; INCLUYE; TRANSDUCTOR DE PULSO REF TN1012/ST; CABLE BIO AMP BLINDADO DE 5 DONDUCTORES REF MLA2540; CABLES CONDUCTORES BLINDADOS (5 BROCES) REF MLA2505; ELECTRODO DE BARRA ESTIMULANTE REF MLADDF30; ELECTRODOS PLANOS PARA EEG REF MLAWBT9; MALETIN SISTEMA DE ENSEÑANZA REF SP0133; MICRÓFONO CARDIACO REF MLT201; MALETIN SISTEMA DE ENSEÑANZA THE SP0133 IS AN EMPLI STAINLESS STELL CASE WITH FOAM INSERTS FOR USE IN PACKAGING MANY OF THE ADINSTRUMENTS, TEACHING SYSTEM REF SP0133 | D88: Académica | E88: Lab. Electromedicina L4 | F88: 45809 | G88: =IFERROR(VLOOKUP(D88,Listas!$A$2:$B$20,2,FALSE()),999) -> 1 | H88: =IF(F88="","Sin fecha",IF(TODAY()-F88>180,"Revisar",IF(TODAY()-F88>90,"Próximo","Vigente"))) -> Revisar | J88: 120 | K88: 105 | L88: 43075 | M88: N
A89: U15201000768 | B89: ANALIZADOR DE ESPECTRO | C89: ANALIZADOR DE ESPECTO - RANGO DE FRECUENCIA 9 KHZ, CON SISTEMA DE DEMODULACION Y ANALISIS AM/FM/ASK/FSK, CONTADOR DE FRECUENCIA INCORPORADO, INCLUYE CABLE DE PODER, GUIA DE INICIO RÁPIDO, CERTIFICADO DE CALIBRACION, CD-ROM (MANUAL DE USUARIO, MANUAL DE PROGRAMACIÓN, SOFTWARE SPECTRUMSHOT, GUIA DE INICIO RAPIDO SPECTRUMSHOT Y CONTOLADORES IVI, MARCA INSTEK, MODELO GSP-9300, PAQUETE DE BATERIAS DC, DURACION REMOTA POR 2 HORAS | D89: Académica | E89: Lab. Electrónica General (L1) | F89: 45809 | G89: =IFERROR(VLOOKUP(D89,Listas!$A$2:$B$20,2,FALSE()),999) -> 1 | H89: =IF(F89="","Sin fecha",IF(TODAY()-F89>180,"Revisar",IF(TODAY()-F89>90,"Próximo","Vigente"))) -> Revisar | J89: 120 | K89: 106 | L89: 43050 | M89: N
...

Sheet Listas
A1: Área | B1: Orden | D1: Dependencia
A2: Académica | B2: 1 | D2: CIPAV
A3: Administrativa | B3: 2 | D3: Energías renovables
A4: Tecnología | B4: 3 | D4: L6
A5: Servicios Generales | B5: 4 | D5: Lab. de Diseño de Sistemas Mecanicos
A6: Financiera | B6: 5 | D6: Lab. de Diseño Mecatronico
A7: Bienestar Universitario | B7: 6 | D7: Lab. Electromedicina L4
A8: Investigación | B8: 7 | D8: Lab. Electrónica General (L1)
A9: Extensión | B9: 8 | D9: Lab. Investiación 1
D10: Lab. Investigación 1
D11: Lab. Investigación 2
D12: Lab. Software Espec. L6
D13: Lab. Telecomunicaciones
D14: Laboratori Fisica Electricidad y Magnetismo
D15: Laboratorio Analisís químico
D16: LABORATORIO DE BIOLOGÍA
D17: LABORATORIO DE BIOLOGÍA MOLECULAR
D18: Laboratorio de combustión
D19: Laboratorio de Metalografía y Tratamientos Termicos
D20: LABORATORIO DE MICROBIOLOGÍA AMBIENTAL
D21: LABORATORIO DE SUELOS, PAVIMENTOS Y CONCRETOS 1
... D29: Redes Computacionales o LM3
