Workbook

Sheet Resumen Ejecutivo
A1: Análisis de Interdependencias Estratégicas — PDI 2026–2029
A2: ¿Qué muestra este archivo? Los 17 proyectos del PDI y cómo se relacionan entre sí. Entre más relaciones tiene un proyecto, mayor coordinación institucional requiere.
A4: Indicadores Globales del Sistema
A5: Proyectos estratégicos | B5: =COUNTA('Nodos y Métricas'!A4:A20) -> 17 | C5: Relaciones identificadas | D5: =COUNTIF(Relaciones!A4:A1048575,"M?-P?") -> 58 | E5: Macroproyectos | F5: =COUNTA('Ranking Macroproyectos'!B4:B8) -> 5
A6: Relaciones de intensidad Alta (puntaje 5) | B6: =COUNTIF(Relaciones!H4:H1048575,"Alta") -> 28 | C6: Relaciones de intensidad Media (puntaje 3) | D6: =COUNTIF(Relaciones!H4:H1048575,"Media") -> 30 | E6: Relaciones de intensidad Baja (puntaje 1) | F6: =COUNTIF(Relaciones!H4:H1048575,"Baja") -> 0
A8: Proyectos por Nivel de Prioridad (¿a cuáles hay que prestarles más atención?)
A9: Prioridad Alta — 8 o más relaciones | B9: =COUNTIF('Nodos y Métricas'!J4:J20,"Prioridad Alta") -> 6 | C9: Prioridad Media — entre 6 y 7 relaciones | D9: =COUNTIF('Nodos y Métricas'!J4:J20,"Prioridad Media") -> 6 | E9: Prioridad Baja — 5 o menos relaciones | F9: =COUNTIF('Nodos y Métricas'!J4:J20,"Prioridad Baja") -> 5
A11: Proyectos por Macroproyecto
A12: Propuesta Formativa Integral y de Calidad | B12: =COUNTIF('Nodos y Métricas'!$C$4:$C$20,"M1") -> 5 | C12: Redes Multidimensionales del Conocimiento | D12: =COUNTIF('Nodos y Métricas'!$C$4:$C$20,"M2") -> 3
A13: Universidad Sostenible | B13: =COUNTIF('Nodos y Métricas'!$C$4:$C$20,"M3") -> 3 | C13: Cultura del Cuidado, la Ética y el Servicio | D13: =COUNTIF('Nodos y Métricas'!$C$4:$C$20,"M4") -> 2
A14: Ecosistema Digital | B14: =COUNTIF('Nodos y Métricas'!$C$4:$C$20,"M5") -> 4
A16: Lectura Rápida del Análisis (generada automáticamente)
A17: {=IFERROR("El macroproyecto con mayor articulación es " & INDEX('Ranking Macroproyectos'!C:C,MATCH(MAX('Ranking Macroproyectos'!E:E),'Ranking Macroproyectos'!E:E,0)) & " (" & INDEX('Ranking Macroproyectos'!B:B,MATCH(MAX('Ranking Macroproyectos'!E:E),'Ranking Macroproyectos'!E:E,0)) & "), con un puntaje total de " & MAX('Ranking Macroproyectos'!E:E) & " puntos y " & INDEX('Ranking Macroproyectos'!F:F,MATCH(MAX('Ranking Macroproyectos'!E:E),'Ranking Macroproyectos'!E:E,0)) & " relaciones totales. Sus proyectos actúan como habilitadores transversales clave del PDI: un retraso en ellos puede generar efecto dominó sobre múltiples frentes estratégicos.","Datos insuficientes para generar lectura automática.")} -> El macroproyecto con mayor articulación es Propuesta Formativa Integral y de Calidad (M1), con un puntaje total de 143 puntos y 37 relaciones totales. Sus proyectos actúan como habilitadores transversales clave del PDI: un retraso en ellos puede generar efecto dominó sobre múltiples frentes estratégicos.
A19: Nota Metodológica
A20: Esta matriz muestra qué proyectos tienen mayor relación estratégica dentro del PDI. Entre más relaciones tenga un proyecto, mayor articulación y coordinación institucional requiere.
A22: =IF(AND(COUNTIF('Nodos y Métricas'!J:J,"Prioridad Alta")+COUNTIF('Nodos y Métricas'!J:J,"Prioridad Media")+COUNTIF('Nodos y Métricas'!J:J,"Prioridad Baja")=17,COUNTA(Relaciones!A:A)-1>0),"✔ Modelo correcto — todos los indicadores calculados","⚠ Revisar inconsistencias en fórmulas o datos") -> ✔ Modelo correcto — todos los indicadores calculados

Sheet Relaciones
A1: Relaciones Estratégicas entre Proyectos — PDI 2026–2029
A2: Cada fila es una relación de un proyecto Origen hacia un proyecto Destino. Puntaje = peso de la relación según intensidad: Alta = 5 · Media = 3 · Baja = 1
A3: ID Origen | B3: Proyecto Origen | C3: Macroproyecto Origen | D3: ID Destino | E3: Proyecto Destino | F3: Macroproyecto Destino | G3: Tipo de Relación | H3: Intensidad | I3: Puntaje | J3: Justificación | K3: Recomendación
A4: M1-P1 | B4: Travesías del Conocimiento | C4: Propuesta Formativa Integral y de Calidad | D4: M3-P1 | E4: Viabilidad Financiera | F4: Universidad Sostenible | G4: Habilitadora | H4: Media | I4: =IF(H4="Alta",5,IF(H4="Media",3,IF(H4="Baja",1,IF(H4="","",0)))) -> 3 | J4: La nueva oferta y microcredenciales generan escenarios para ingresos y sostenibilidad financiera. | K4: Usar escenarios de demanda y empleabilidad como insumo del modelo financiero.
A5: M1-P1 | B5: Travesías del Conocimiento | C5: Propuesta Formativa Integral y de Calidad | D5: M1-P5 | E5: Trayectorias de Futuro | F5: Propuesta Formativa Integral y de Calidad | G5: Habilitadora | H5: Alta | I5: =IF(H5="Alta",5,IF(H5="Media",3,IF(H5="Baja",1,IF(H5="","",0)))) -> 5 | J5: La oferta académica flexible y microcredenciales alimenta la articulación media-superior. | K5: Alinear currículos articulados con rutas de aprendizaje y oferta institucional.
A6: M1-P1 | B6: Travesías del Conocimiento | C6: Propuesta Formativa Integral y de Calidad | D6: M1-P3 | E6: Tránsito Vital | F6: Propuesta Formativa Integral y de Calidad | G6: Complementariedad | H6: Alta | I6: =IF(H6="Alta",5,IF(H6="Media",3,IF(H6="Baja",1,IF(H6="","",0)))) -> 5 | J6: El diseño curricular y ambientes de aprendizaje inciden en permanencia, logro académico y empleabilidad. | K6: Asegurar que el modelo de éxito estudiantil dialogue con trayectorias curriculares.
A7: M1-P1 | B7: Travesías del Conocimiento | C7: Propuesta Formativa Integral y de Calidad | D7: M5-P3 | E7: Herramientas Digitales | F7: Ecosistema Digital | G7: Complementariedad | H7: Alta | I7: =IF(H7="Alta",5,IF(H7="Media",3,IF(H7="Baja",1,IF(H7="","",0)))) -> 5 | J7: M1-P1 incluye ambientes virtuales; M5-P3 incluye herramientas de aprendizaje y modelo tecnológico pedagógico híbrido. | K7: Unificar indicador, línea base, responsable y alcance de ambientes virtuales.
A8: M1-P1 | B8: Travesías del Conocimiento | C8: Propuesta Formativa Integral y de Calidad | D8: M2-P2 | E8: Misiones Académicas y Científicas | F8: Redes Multidimensionales del Conocimiento | G8: Complementariedad | H8: Media | I8: =IF(H8="Alta",5,IF(H8="Media",3,IF(H8="Baja",1,IF(H8="","",0)))) -> 3 | J8: La oferta académica y currículos transdisciplinares pueden articularse con misiones y retos territoriales. | K8: Usar misiones como escenarios de aprendizaje interdisciplinar.
A9: M1-P1 | B9: Travesías del Conocimiento | C9: Propuesta Formativa Integral y de Calidad | D9: M2-P3 | E9: Laboratorios Vivos de Innovación | F9: Redes Multidimensionales del Conocimiento | G9: Complementariedad | H9: Media | I9: =IF(H9="Alta",5,IF(H9="Media",3,IF(H9="Baja",1,IF(H9="","",0)))) -> 3 | J9: Los laboratorios vivos pueden funcionar como ambientes de aprendizaje territorial y transdisciplinar. | K9: Integrar living labs a cursos, rutas y microcredenciales.
A10: M1-P2 | B10: Aseguramiento de la Calidad (SIAC) | C10: Propuesta Formativa Integral y de Calidad | D10: M1-P1 | E10: Travesías del Conocimiento | F10: Propuesta Formativa Integral y de Calidad | G10: Habilitadora | H10: Alta | I10: =IF(H10="Alta",5,IF(H10="Media",3,IF(H10="Baja",1,IF(H10="","",0)))) -> 5 | J10: El SIAC y estándares de calidad orientan creación, actualización y acreditación de programas. | K10: Asegurar que nuevos diseños curriculares nazcan alineados con SIAC.
A11: M1-P2 | B11: Aseguramiento de la Calidad (SIAC) | C11: Propuesta Formativa Integral y de Calidad | D11: M1-P3 | E11: Tránsito Vital | F11: Propuesta Formativa Integral y de Calidad | G11: Habilitadora | H11: Media | I11: =IF(H11="Alta",5,IF(H11="Media",3,IF(H11="Baja",1,IF(H11="","",0)))) -> 3 | J11: La autorregulación y mejora continua soportan estrategias de permanencia y desempeño Saber Pro. | K11: Conectar resultados de autoevaluación con indicadores de trayectoria estudiantil.
A12: M1-P2 | B12: Aseguramiento de la Calidad (SIAC) | C12: Propuesta Formativa Integral y de Calidad | D12: M1-P4 | E12: Voces y Saberes | F12: Propuesta Formativa Integral y de Calidad | G12: Habilitadora | H12: Media | I12: =IF(H12="Alta",5,IF(H12="Media",3,IF(H12="Baja",1,IF(H12="","",0)))) -> 3 | J12: El SIAC exige capacidades profesorales coherentes con docencia transformadora y estándares de calidad. | K12: Cruzar plan profesoral con brechas identificadas en autoevaluación.
A13: M1-P2 | B13: Aseguramiento de la Calidad (SIAC) | C13: Propuesta Formativa Integral y de Calidad | D13: M3-P2 | E13: Autorregulación Institucional | F13: Universidad Sostenible | G13: Complementariedad | H13: Alta | I13: =IF(H13="Alta",5,IF(H13="Media",3,IF(H13="Baja",1,IF(H13="","",0)))) -> 5 | J13: El SIAC aporta metodología de autorregulación para la reorganización y actualización de procesos. | K13: Usar SIAC como marco de seguimiento de procesos reorganizados.
A14: M1-P3 | B14: Tránsito Vital | C14: Propuesta Formativa Integral y de Calidad | D14: M4-P1 | E14: Cuidado Colectivo | F14: Cultura del Cuidado, la Ética y el Servicio | G14: Complementariedad | H14: Media | I14: =IF(H14="Alta",5,IF(H14="Media",3,IF(H14="Baja",1,IF(H14="","",0)))) -> 3 | J14: Egresados y estudiantes pueden participar en actividades de bienestar bajo modelos de capacidades colectivas. | K14: Diseñar oferta de bienestar para estudiantes, graduados y comunidad.
A15: M1-P3 | B15: Tránsito Vital | C15: Propuesta Formativa Integral y de Calidad | D15: M1-P5 | E15: Trayectorias de Futuro | F15: Propuesta Formativa Integral y de Calidad | G15: Complementariedad | H15: Media | I15: =IF(H15="Alta",5,IF(H15="Media",3,IF(H15="Baja",1,IF(H15="","",0)))) -> 3 | J15: La orientación vocacional y transición media-superior se conecta con permanencia y éxito estudiantil. | K15: Articular acompañamiento desde educación media hasta primer año universitario.
... A61: M5-P4 | B61: Universidad Ágil | C61: Ecosistema Digital | D61: M3-P1 | E61: Viabilidad Financiera | F61: Universidad Sostenible | G61: Habilitadora | H61: Media | I61: =IF(H61="Alta",5,IF(H61="Media",3,IF(H61="Baja",1,IF(H61="","",0)))) -> 3 | J61: Procesos ágiles y automatización pueden mejorar eficiencia y optimización de recursos. | K61: Medir ahorros de tiempo/costo en procesos priorizados.
I62: =IF(H62="Alta",5,IF(H62="Media",3,IF(H62="Baja",1,IF(H62="","",0))))
I63: =IF(H63="Alta",5,IF(H63="Media",3,IF(H63="Baja",1,IF(H63="","",0))))
A64: Leyenda de Tipos de Relación e Intensidades
A65: Habilitadora | B65: Relación en la que un proyecto genera condiciones, capacidades, insumos o soportes que facilitan y potencian el desarrollo o cumplimiento de otro proyecto.
A66: Complementariedad | B66: Relación en la que dos proyectos se articulan y fortalecen mutuamente, generando aportes recíprocos para el cumplimiento de objetivos comunes.
A67: Dependencia | B67: Relación en la que el avance, desarrollo o cumplimiento de un proyecto está condicionado parcial o totalmente por los resultados, insumos o avances generados por otro proyecto.
A68: Alta (Puntaje 5) | B68: Vínculo fuerte y directo — gestión prioritaria.
A69: Media (Puntaje 3) | B69: Vínculo relevante — articular en el seguimiento del PDI.
I70: =IF(H70="Alta",5,IF(H70="Media",3,IF(H70="Baja",1,IF(H70="","",0))))
I71: =IF(H71="Alta",5,IF(H71="Media",3,IF(H71="Baja",1,IF(H71="","",0))))
I72: =IF(H72="Alta",5,IF(H72="Media",3,IF(H72="Baja",1,IF(H72="","",0))))
I73: =IF(H73="Alta",5,IF(H73="Media",3,IF(H73="Baja",1,IF(H73="","",0))))
I74: =IF(H74="Alta",5,IF(H74="Media",3,IF(H74="Baja",1,IF(H74="","",0))))
I75: =IF(H75="Alta",5,IF(H75="Media",3,IF(H75="Baja",1,IF(H75="","",0))))
I76: =IF(H76="Alta",5,IF(H76="Media",3,IF(H76="Baja",1,IF(H76="","",0))))
I77: =IF(H77="Alta",5,IF(H77="Media",3,IF(H77="Baja",1,IF(H77="","",0))))
I78: =IF(H78="Alta",5,IF(H78="Media",3,IF(H78="Baja",1,IF(H78="","",0))))
I79: =IF(H79="Alta",5,IF(H79="Media",3,IF(H79="Baja",1,IF(H79="","",0))))
I80: =IF(H80="Alta",5,IF(H80="Media",3,IF(H80="Baja",1,IF(H80="","",0))))
I81: =IF(H81="Alta",5,IF(H81="Media",3,IF(H81="Baja",1,IF(H81="","",0))))
... I202: =IF(H202="Alta",5,IF(H202="Media",3,IF(H202="Baja",1,IF(H202="","",0))))

Sheet Nodos y Métricas
A1: Métricas de Conectividad por Proyecto — PDI 2026–2029
A2: ¿Cómo leer esta hoja? 'Relaciones que genera' = cuántos proyectos recibe el impacto de este. 'Relaciones que recibe' = de cuántos proyectos depende. 'Puntaje Total' = suma ponderada (Alta=5, Media=3, Baja=1).
A3: Código | B3: Proyecto | C3: Macro | D3: Macroproyecto | E3: Relaciones que genera | F3: Relaciones que recibe | G3: Total Relaciones | H3: Puntaje Total | I3: Nivel de Articulación | J3: Prioridad de Gestión | K3: Lectura Rápida
A4: M1-P1 | B4: Travesías del Conocimiento | C4: M1 | D4: Propuesta Formativa Integral y de Calidad | E4: =COUNTIF(Relaciones!A:A,A4) -> 6 | F4: =COUNTIF(Relaciones!D:D,A4) -> 5 | G4: =E4+F4 -> 11 | H4: =SUMIF(Relaciones!A:A,A4,Relaciones!I:I)+SUMIF(Relaciones!D:D,A4,Relaciones!I:I) -> 47 | I4: =IF(G4>=8,"Alta",IF(G4>=6,"Media","Baja")) -> Alta | J4: =IF(G4>=8,"Prioridad Alta",IF(G4>=6,"Prioridad Media","Prioridad Baja")) -> Prioridad Alta | K4: =IF(J4="Prioridad Alta","Requiere articulación alta – seguimiento prioritario",IF(J4="Prioridad Media","Coordinación moderada – articular en seguimiento PDI","Baja necesidad de articulación – monitoreo periódico")) -> Requiere articulación alta – seguimiento prioritario
A5: M1-P2 | B5: Aseguramiento de la Calidad (SIAC) | C5: M1 | D5: Propuesta Formativa Integral y de Calidad | E5: =COUNTIF(Relaciones!A:A,A5) -> 4 | F5: =COUNTIF(Relaciones!D:D,A5) -> 3 | G5: =E5+F5 -> 7 | H5: =SUMIF(Relaciones!A:A,A5,Relaciones!I:I)+SUMIF(Relaciones!D:D,A5,Relaciones!I:I) -> 27 | I5: =IF(G5>=8,"Alta",IF(G5>=6,"Media","Baja")) -> Media | J5: =IF(G5>=8,"Prioridad Alta",IF(G5>=6,"Prioridad Media","Prioridad Baja")) -> Prioridad Media | K5: =IF(J5="Prioridad Alta","Requiere articulación alta – seguimiento prioritario",IF(J5="Prioridad Media","Coordinación moderada – articular en seguimiento PDI","Baja necesidad de articulación – monitoreo periódico")) -> Coordinación moderada – articular en seguimiento PDI
A6: M1-P3 | B6: Tránsito Vital | C6: M1 | D6: Propuesta Formativa Integral y de Calidad | E6: =COUNTIF(Relaciones!A:A,A6) -> 2 | F6: =COUNTIF(Relaciones!D:D,A6) -> 6 | G6: =E6+F6 -> 8 | H6: =SUMIF(Relaciones!A:A,A6,Relaciones!I:I)+SUMIF(Relaciones!D:D,A6,Relaciones!I:I) -> 28 | I6: =IF(G6>=8,"Alta",IF(G6>=6,"Media","Baja")) -> Alta | J6: =IF(G6>=8,"Prioridad Alta",IF(G6>=6,"Prioridad Media","Prioridad Baja")) -> Prioridad Alta | K6: =IF(J6="Prioridad Alta","Requiere articulación alta – seguimiento prioritario",IF(J6="Prioridad Media","Coordinación moderada – articular en seguimiento PDI","Baja necesidad de articulación – monitoreo periódico")) -> Requiere articulación alta – seguimiento prioritario
A7: M1-P4 | B7: Voces y Saberes | C7: M1 | D7: Propuesta Formativa Integral y de Calidad | E7: =COUNTIF(Relaciones!A:A,A7) -> 5 | F7: =COUNTIF(Relaciones!D:D,A7) -> 2 | G7: =E7+F7 -> 7 | H7: =SUMIF(Relaciones!A:A,A7,Relaciones!I:I)+SUMIF(Relaciones!D:D,A7,Relaciones!I:I) -> 27 | I7: =IF(G7>=8,"Alta",IF(G7>=6,"Media","Baja")) -> Media | J7: =IF(G7>=8,"Prioridad Alta",IF(G7>=6,"Prioridad Media","Prioridad Baja")) -> Prioridad Media | K7: =IF(J7="Prioridad Alta","Requiere articulación alta – seguimiento prioritario",IF(J7="Prioridad Media","Coordinación moderada – articular en seguimiento PDI","Baja necesidad de articulación – monitoreo periódico")) -> Coordinación moderada – articular en seguimiento PDI
A8: M1-P5 | B8: Trayectorias de Futuro | C8: M1 | D8: Propuesta Formativa Integral y de Calidad | E8: =COUNTIF(Relaciones!A:A,A8) -> 2 | F8: =COUNTIF(Relaciones!D:D,A8) -> 2 | G8: =E8+F8 -> 4 | H8: =SUMIF(Relaciones!A:A,A8,Relaciones!I:I)+SUMIF(Relaciones!D:D,A8,Relaciones!I:I) -> 14 | I8: =IF(G8>=8,"Alta",IF(G8>=6,"Media","Baja")) -> Baja | J8: =IF(G8>=8,"Prioridad Alta",IF(G8>=6,"Prioridad Media","Prioridad Baja")) -> Prioridad Baja | K8: =IF(J8="Prioridad Alta","Requiere articulación alta – seguimiento prioritario",IF(J8="Prioridad Media","Coordinación moderada – articular en seguimiento PDI","Baja necesidad de articulación – monitoreo periódico")) -> Baja necesidad de articulación – monitoreo periódico
A9: M2-P1 | B9: Redes del Conocimiento | C9: M2 | D9: Redes Multidimensionales del Conocimiento | E9: =COUNTIF(Relaciones!A:A,A9) -> 3 | F9: =COUNTIF(Relaciones!D:D,A9) -> 4 | G9: =E9+F9 -> 7 | H9: =SUMIF(Relaciones!A:A,A9,Relaciones!I:I)+SUMIF(Relaciones!D:D,A9,Relaciones!I:I) -> 27 | I9: =IF(G9>=8,"Alta",IF(G9>=6,"Media","Baja")) -> Media | J9: =IF(G9>=8,"Prioridad Alta",IF(G9>=6,"Prioridad Media","Prioridad Baja")) -> Prioridad Media | K9: =IF(J9="Prioridad Alta","Requiere articulación alta – seguimiento prioritario",IF(J9="Prioridad Media","Coordinación moderada – articular en seguimiento PDI","Baja necesidad de articulación – monitoreo periódico")) -> Coordinación moderada – articular en seguimiento PDI
A10: M2-P2 | B10: Misiones Académicas y Científicas | C10: M2 | D10: Redes Multidimensionales del Conocimiento | E10: =COUNTIF(Relaciones!A:A,A10) -> 2 | F10: =COUNTIF(Relaciones!D:D,A10) -> 6 | G10: =E10+F10 -> 8 | H10: =SUMIF(Relaciones!A:A,A10,Relaciones!I:I)+SUMIF(Relaciones!D:D,A10,Relaciones!I:I) -> 32 | I10: =IF(G10>=8,"Alta",IF(G10>=6,"Media","Baja")) -> Alta | J10: =IF(G10>=8,"Prioridad Alta",IF(G10>=6,"Prioridad Media","Prioridad Baja")) -> Prioridad Alta | K10: =IF(J10="Prioridad Alta","Requiere articulación alta – seguimiento prioritario",IF(J10="Prioridad Media","Coordinación moderada – articular en seguimiento PDI","Baja necesidad de articulación – monitoreo periódico")) -> Requiere articulación alta – seguimiento prioritario
A11: M2-P3 | B11: Laboratorios Vivos de Innovación | C11: M2 | D11: Redes Multidimensionales del Conocimiento | E11: =COUNTIF(Relaciones!A:A,A11) -> 2 | F11: =COUNTIF(Relaciones!D:D,A11) -> 6 | G11: =E11+F11 -> 8 | H11: =SUMIF(Relaciones!A:A,A11,Relaciones!I:I)+SUMIF(Relaciones!D:D,A11,Relaciones!I:I) -> 32 | I11: =IF(G11>=8,"Alta",IF(G11>=6,"Media","Baja")) -> Alta | J11: =IF(G11>=8,"Prioridad Alta",IF(G11>=6,"Prioridad Media","Prioridad Baja")) -> Prioridad Alta | K11: =IF(J11="Prioridad Alta","Requiere articulación alta – seguimiento prioritario",IF(J11="Prioridad Media","Coordinación moderada – articular en seguimiento PDI","Baja necesidad de articulación – monitoreo periódico")) -> Requiere articulación alta – seguimiento prioritario
A12: M3-P1 | B12: Viabilidad Financiera | C12: M3 | D12: Universidad Sostenible | E12: =COUNTIF(Relaciones!A:A,A12) -> 7 | F12: =COUNTIF(Relaciones!D:D,A12) -> 2 | G12: =E12+F12 -> 9 | H12: =SUMIF(Relaciones!A:A,A12,Relaciones!I:I)+SUMIF(Relaciones!D:D,A12,Relaciones!I:I) -> 31 | I12: =IF(G12>=8,"Alta",IF(G12>=6,"Media","Baja")) -> Alta | J12: =IF(G12>=8,"Prioridad Alta",IF(G12>=6,"Prioridad Media","Prioridad Baja")) -> Prioridad Alta | K12: =IF(J12="Prioridad Alta","Requiere articulación alta – seguimiento prioritario",IF(J12="Prioridad Media","Coordinación moderada – articular en seguimiento PDI","Baja necesidad de articulación – monitoreo periódico")) -> Requiere articulación alta – seguimiento prioritario
A13: M3-P2 | B13: Autorregulación Institucional | C13: M3 | D13: Universidad Sostenible | E13: =COUNTIF(Relaciones!A:A,A13) -> 4 | F13: =COUNTIF(Relaciones!D:D,A13) -> 2 | G13: =E13+F13 -> 6 | H13: =SUMIF(Relaciones!A:A,A13,Relaciones!I:I)+SUMIF(Relaciones!D:D,A13,Relaciones!I:I) -> 24 | I13: =IF(G13>=8,"Alta",IF(G13>=6,"Media","Baja")) -> Media | J13: =IF(G13>=8,"Prioridad Alta",IF(G13>=6,"Prioridad Media","Prioridad Baja")) -> Prioridad Media | K13: =IF(J13="Prioridad Alta","Requiere articulación alta – seguimiento prioritario",IF(J13="Prioridad Media","Coordinación moderada – articular en seguimiento PDI","Baja necesidad de articulación – monitoreo periódico")) -> Coordinación moderada – articular en seguimiento PDI
A14: M3-P3 | B14: Alianzas y Cooperación para la Sostenibilidad | C14: M3 | D14: Universidad Sostenible | E14: =COUNTIF(Relaciones!A:A,A14) -> 1 | F14: =COUNTIF(Relaciones!D:D,A14) -> 4 | G14: =E14+F14 -> 5 | H14: =SUMIF(Relaciones!A:A,A14,Relaciones!I:I)+SUMIF(Relaciones!D:D,A14,Relaciones!I:I) -> 19 | I14: =IF(G14>=8,"Alta",IF(G14>=6,"Media","Baja")) -> Baja | J14: =IF(G14>=8,"Prioridad Alta",IF(G14>=6,"Prioridad Media","Prioridad Baja")) -> Prioridad Baja | K14: =IF(J14="Prioridad Alta","Requiere articulación alta – seguimiento prioritario",IF(J14="Prioridad Media","Coordinación moderada – articular en seguimiento PDI","Baja necesidad de articulación – monitoreo periódico")) -> Baja necesidad de articulación – monitoreo periódico
A15: M4-P1 | B15: Cuidado Colectivo | C15: M4 | D15: Cultura del Cuidado, la Ética y el Servicio | E15: =COUNTIF(Relaciones!A:A,A15) -> 2 | F15: =COUNTIF(Relaciones!D:D,A15) -> 2 | G15: =E15+F15 -> 4 | H15: =SUMIF(Relaciones!A:A,A15,Relaciones!I:I)+SUMIF(Relaciones!D:D,A15,Relaciones!I:I) -> 16 | I15: =IF(G15>=8,"Alta",IF(G15>=6,"Media","Baja")) -> Baja | J15: =IF(G15>=8,"Prioridad Alta",IF(G15>=6,"Prioridad Media","Prioridad Baja")) -> Prioridad Baja | K15: =IF(J15="Prioridad Alta","Requiere articulación alta – seguimiento prioritario",IF(J15="Prioridad Media","Coordinación moderada – articular en seguimiento PDI","Baja necesidad de articulación – monitoreo periódico")) -> Baja necesidad de articulación – monitoreo periódico
... A20: M5-P4 | B20: Universidad Ágil | C20: M5 | D20: Ecosistema Digital | E20: =COUNTIF(Relaciones!A:A,A20) -> 4 | F20: =COUNTIF(Relaciones!D:D,A20) -> 3 | G20: =E20+F20 -> 7 | H20: =SUMIF(Relaciones!A:A,A20,Relaciones!I:I)+SUMIF(Relaciones!D:D,A20,Relaciones!I:I) -> 29 | I20: =IF(G20>=8,"Alta",IF(G20>=6,"Media","Baja")) -> Media | J20: =IF(G20>=8,"Prioridad Alta",IF(G20>=6,"Prioridad Media","Prioridad Baja")) -> Prioridad Media | K20: =IF(J20="Prioridad Alta","Requiere articulación alta – seguimiento prioritario",IF(J20="Prioridad Media","Coordinación moderada – articular en seguimiento PDI","Baja necesidad de articulación – monitoreo periódico")) -> Coordinación moderada – articular en seguimiento PDI
A22: =IF(COUNTA(A4:A20)=17,"✔ Modelo correcto — 17 proyectos activos","⚠ Revisar: número de proyectos inesperado") -> ✔ Modelo correcto — 17 proyectos activos

Sheet Ranking Proyectos
A1: Ranking de Proyectos por Conectividad — PDI 2026–2029
A2: Ordenados de mayor a menor Puntaje Total. El ranking se recalcula automáticamente si cambian las relaciones en la hoja 'Relaciones'.
A3: # | B3: Código | C3: Proyecto | D3: Macro | E3: Puntaje Total | F3: Total Relaciones | G3: Prioridad de Gestión | H3: Lectura Rápida
A4: =IFERROR(RANK(E4,E$4:E$20,0),"") -> 1 | B4: ='Nodos y Métricas'!A19 -> M5-P3 | C4: ='Nodos y Métricas'!B19 -> Herramientas Digitales | D4: ='Nodos y Métricas'!C19 -> M5 | E4: ='Nodos y Métricas'!H19 -> 49 | F4: ='Nodos y Métricas'!G19 -> 11 | G4: ='Nodos y Métricas'!J19 -> Prioridad Alta | H4: ='Nodos y Métricas'!K19 -> Requiere articulación alta – seguimiento prioritario
A5: =IFERROR(RANK(E5,E$4:E$20,0),"") -> 2 | B5: ='Nodos y Métricas'!A4 -> M1-P1 | C5: ='Nodos y Métricas'!B4 -> Travesías del Conocimiento | D5: ='Nodos y Métricas'!C4 -> M1 | E5: ='Nodos y Métricas'!H4 -> 47 | F5: ='Nodos y Métricas'!G4 -> 11 | G5: ='Nodos y Métricas'!J4 -> Prioridad Alta | H5: ='Nodos y Métricas'!K4 -> Requiere articulación alta – seguimiento prioritario
A6: =IFERROR(RANK(E6,E$4:E$20,0),"") -> 3 | B6: ='Nodos y Métricas'!A10 -> M2-P2 | C6: ='Nodos y Métricas'!B10 -> Misiones Académicas y Científicas | D6: ='Nodos y Métricas'!C10 -> M2 | E6: ='Nodos y Métricas'!H10 -> 32 | F6: ='Nodos y Métricas'!G10 -> 8 | G6: ='Nodos y Métricas'!J10 -> Prioridad Alta | H6: ='Nodos y Métricas'!K10 -> Requiere articulación alta – seguimiento prioritario
A7: =IFERROR(RANK(E7,E$4:E$20,0),"") -> 3 | B7: ='Nodos y Métricas'!A11 -> M2-P3 | C7: ='Nodos y Métricas'!B11 -> Laboratorios Vivos de Innovación | D7: ='Nodos y Métricas'!C11 -> M2 | E7: ='Nodos y Métricas'!H11 -> 32 | F7: ='Nodos y Métricas'!G11 -> 8 | G7: ='Nodos y Métricas'!J11 -> Prioridad Alta | H7: ='Nodos y Métricas'!K11 -> Requiere articulación alta – seguimiento prioritario
A8: =IFERROR(RANK(E8,E$4:E$20,0),"") -> 5 | B8: ='Nodos y Métricas'!A12 -> M3-P1 | C8: ='Nodos y Métricas'!B12 -> Viabilidad Financiera | D8: ='Nodos y Métricas'!C12 -> M3 | E8: ='Nodos y Métricas'!H12 -> 31 | F8: ='Nodos y Métricas'!G12 -> 9 | G8: ='Nodos y Métricas'!J12 -> Prioridad Alta | H8: ='Nodos y Métricas'!K12 -> Requiere articulación alta – seguimiento prioritario
A9: =IFERROR(RANK(E9,E$4:E$20,0),"") -> 6 | B9: ='Nodos y Métricas'!A20 -> M5-P4 | C9: ='Nodos y Métricas'!B20 -> Universidad Ágil | D9: ='Nodos y Métricas'!C20 -> M5 | E9: ='Nodos y Métricas'!H20 -> 29 | F9: ='Nodos y Métricas'!G20 -> 7 | G9: ='Nodos y Métricas'!J20 -> Prioridad Media | H9: ='Nodos y Métricas'!K20 -> Coordinación moderada – articular en seguimiento PDI
A10: =IFERROR(RANK(E10,E$4:E$20,0),"") -> 7 | B10: ='Nodos y Métricas'!A6 -> M1-P3 | C10: ='Nodos y Métricas'!B6 -> Tránsito Vital | D10: ='Nodos y Métricas'!C6 -> M1 | E10: ='Nodos y Métricas'!H6 -> 28 | F10: ='Nodos y Métricas'!G6 -> 8 | G10: ='Nodos y Métricas'!J6 -> Prioridad Alta | H10: ='Nodos y Métricas'!K6 -> Requiere articulación alta – seguimiento prioritario
A11: =IFERROR(RANK(E11,E$4:E$20,0),"") -> 8 | B11: ='Nodos y Métricas'!A5 -> M1-P2 | C11: ='Nodos y Métricas'!B5 -> Aseguramiento de la Calidad (SIAC) | D11: ='Nodos y Métricas'!C5 -> M1 | E11: ='Nodos y Métricas'!H5 -> 27 | F11: ='Nodos y Métricas'!G5 -> 7 | G11: ='Nodos y Métricas'!J5 -> Prioridad Media | H11: ='Nodos y Métricas'!K5 -> Coordinación moderada – articular en seguimiento PDI
A12: =IFERROR(RANK(E12,E$4:E$20,0),"") -> 8 | B12: ='Nodos y Métricas'!A7 -> M1-P4 | C12: ='Nodos y Métricas'!B7 -> Voces y Saberes | D12: ='Nodos y Métricas'!C7 -> M1 | E12: ='Nodos y Métricas'!H7 -> 27 | F12: ='Nodos y Métricas'!G7 -> 7 | G12: ='Nodos y Métricas'!J7 -> Prioridad Media | H12: ='Nodos y Métricas'!K7 -> Coordinación moderada – articular en seguimiento PDI
A13: =IFERROR(RANK(E13,E$4:E$20,0),"") -> 8 | B13: ='Nodos y Métricas'!A9 -> M2-P1 | C13: ='Nodos y Métricas'!B9 -> Redes del Conocimiento | D13: ='Nodos y Métricas'!C9 -> M2 | E13: ='Nodos y Métricas'!H9 -> 27 | F13: ='Nodos y Métricas'!G9 -> 7 | G13: ='Nodos y Métricas'!J9 -> Prioridad Media | H13: ='Nodos y Métricas'!K9 -> Coordinación moderada – articular en seguimiento PDI
A14: =IFERROR(RANK(E14,E$4:E$20,0),"") -> 11 | B14: ='Nodos y Métricas'!A13 -> M3-P2 | C14: ='Nodos y Métricas'!B13 -> Autorregulación Institucional | D14: ='Nodos y Métricas'!C13 -> M3 | E14: ='Nodos y Métricas'!H13 -> 24 | F14: ='Nodos y Métricas'!G13 -> 6 | G14: ='Nodos y Métricas'!J13 -> Prioridad Media | H14: ='Nodos y Métricas'!K13 -> Coordinación moderada – articular en seguimiento PDI
A15: =IFERROR(RANK(E15,E$4:E$20,0),"") -> 12 | B15: ='Nodos y Métricas'!A17 -> M5-P1 | C15: ='Nodos y Métricas'!B17 -> Madurez Digital Institucional | D15: ='Nodos y Métricas'!C17 -> M5 | E15: ='Nodos y Métricas'!H17 -> 22 | F15: ='Nodos y Métricas'!G17 -> 6 | G15: ='Nodos y Métricas'!J17 -> Prioridad Media | H15: ='Nodos y Métricas'!K17 -> Coordinación moderada – articular en seguimiento PDI
A16: =IFERROR(RANK(E16,E$4:E$20,0),"") -> 13 | B16: ='Nodos y Métricas'!A16 -> M4-P2 | C16: ='Nodos y Métricas'!B16 -> Cultura del Servicio | D16: ='Nodos y Métricas'!C16 -> M4 | E16: ='Nodos y Métricas'!H16 -> 21 | F16: ='Nodos y Métricas'!G16 -> 5 | G16: ='Nodos y Métricas'!J16 -> Prioridad Baja | H16: ='Nodos y Métricas'!K16 -> Baja necesidad de articulación – monitoreo periódico
A17: =IFERROR(RANK(E17,E$4:E$20,0),"") -> 14 | B17: ='Nodos y Métricas'!A14 -> M3-P3 | C17: ='Nodos y Métricas'!B14 -> Alianzas y Cooperación para la Sostenibilidad | D17: ='Nodos y Métricas'!C14 -> M3 | E17: ='Nodos y Métricas'!H14 -> 19 | F17: ='Nodos y Métricas'!G14 -> 5 | G17: ='Nodos y Métricas'!J14 -> Prioridad Baja | H17: ='Nodos y Métricas'!K14 -> Baja necesidad de articulación – monitoreo periódico
A18: =IFERROR(RANK(E18,E$4:E$20,0),"") -> 15 | B18: ='Nodos y Métricas'!A15 -> M4-P1 | C18: ='Nodos y Métricas'!B15 -> Cuidado Colectivo | D18: ='Nodos y Métricas'!C15 -> M4 | E18: ='Nodos y Métricas'!H15 -> 16 | F18: ='Nodos y Métricas'!G15 -> 4 | G18: ='Nodos y Métricas'!J15 -> Prioridad Baja | H18: ='Nodos y Métricas'!K15 -> Baja necesidad de articulación – monitoreo periódico
A19: =IFERROR(RANK(E19,E$4:E$20,0),"") -> 16 | B19: ='Nodos y Métricas'!A18 -> M5-P2 | C19: ='Nodos y Métricas'!B18 -> Infraestructura Tecnológica | D19: ='Nodos y Métricas'!C18 -> M5 | E19: ='Nodos y Métricas'!H18 -> 15 | F19: ='Nodos y Métricas'!G18 -> 3 | G19: ='Nodos y Métricas'!J18 -> Prioridad Baja | H19: ='Nodos y Métricas'!K18 -> Baja necesidad de articulación – monitoreo periódico
A20: =IFERROR(RANK(E20,E$4:E$20,0),"") -> 17 | B20: ='Nodos y Métricas'!A8 -> M1-P5 | C20: ='Nodos y Métricas'!B8 -> Trayectorias de Futuro | D20: ='Nodos y Métricas'!C8 -> M1 | E20: ='Nodos y Métricas'!H8 -> 14 | F20: ='Nodos y Métricas'!G8 -> 4 | G20: ='Nodos y Métricas'!J8 -> Prioridad Baja | H20: ='Nodos y Métricas'!K8 -> Baja necesidad de articulación – monitoreo periódico
A21: =IF(COUNTA(B4:B20)=17,"✔ Ranking completo — 17 proyectos","⚠ Revisar: número de proyectos incorrecto") -> ✔ Ranking completo — 17 proyectos

Sheet Ranking Macroproyectos
A1: Ranking de Macroproyectos — PDI 2026–2029
A2: Agrega puntajes y relaciones de todos los proyectos que pertenecen a cada macroproyecto.
A3: # | B3: Código | C3: Macroproyecto | D3: N° Proyectos | E3: Puntaje Ponderado Total | F3: Total Relaciones
A4: =IFERROR(RANK(E4,E$4:E$8,0),"") -> 1 | B4: M1 | C4: Propuesta Formativa Integral y de Calidad | D4: =COUNTIF('Nodos y Métricas'!C:C,B4) -> 5 | E4: =SUMIF('Nodos y Métricas'!C:C,B4,'Nodos y Métricas'!H:H) -> 143 | F4: =SUMIF('Nodos y Métricas'!C:C,B4,'Nodos y Métricas'!G:G) -> 37
A5: =IFERROR(RANK(E5,E$4:E$8,0),"") -> 3 | B5: M2 | C5: Redes Multidimensionales del Conocimiento | D5: =COUNTIF('Nodos y Métricas'!C:C,B5) -> 3 | E5: =SUMIF('Nodos y Métricas'!C:C,B5,'Nodos y Métricas'!H:H) -> 91 | F5: =SUMIF('Nodos y Métricas'!C:C,B5,'Nodos y Métricas'!G:G) -> 23
A6: =IFERROR(RANK(E6,E$4:E$8,0),"") -> 4 | B6: M3 | C6: Universidad Sostenible | D6: =COUNTIF('Nodos y Métricas'!C:C,B6) -> 3 | E6: =SUMIF('Nodos y Métricas'!C:C,B6,'Nodos y Métricas'!H:H) -> 74 | F6: =SUMIF('Nodos y Métricas'!C:C,B6,'Nodos y Métricas'!G:G) -> 20
A7: =IFERROR(RANK(E7,E$4:E$8,0),"") -> 5 | B7: M4 | C7: Cultura del Cuidado, la Ética y el Servicio | D7: =COUNTIF('Nodos y Métricas'!C:C,B7) -> 2 | E7: =SUMIF('Nodos y Métricas'!C:C,B7,'Nodos y Métricas'!H:H) -> 37 | F7: =SUMIF('Nodos y Métricas'!C:C,B7,'Nodos y Métricas'!G:G) -> 9
A8: =IFERROR(RANK(E8,E$4:E$8,0),"") -> 2 | B8: M5 | C8: Ecosistema Digital | D8: =COUNTIF('Nodos y Métricas'!C:C,B8) -> 4 | E8: =SUMIF('Nodos y Métricas'!C:C,B8,'Nodos y Métricas'!H:H) -> 115 | F8: =SUMIF('Nodos y Métricas'!C:C,B8,'Nodos y Métricas'!G:G) -> 27
A9: =IF(SUM(D4:D8)=COUNTA('Nodos y Métricas'!A4:A20),"✔ Macroproyectos correctos — suman 17 proyectos","⚠ Revisar: conteo de proyectos no cierra en 17") -> ✔ Macroproyectos correctos — suman 17 proyectos

Sheet Datos para Gráficos
A1: NODOS — Proyectos estratégicos PDI 2026–2029 (17 proyectos · fuente: Nodos y Métricas)
A2: ID_Proyecto | B2: Proyecto | C2: Macroproyecto | D2: Puntaje_Total | E2: Nivel_Articulacion | F2: Prioridad_Gestion
A3: =IFERROR(IF('Nodos y Métricas'!A4="","",'Nodos y Métricas'!A4),"") -> M1-P1 | B3: =IFERROR(IF('Nodos y Métricas'!B4="","",'Nodos y Métricas'!B4),"") -> Travesías del Conocimiento | C3: =IFERROR(IF('Nodos y Métricas'!C4="","",'Nodos y Métricas'!C4),"") -> M1 | D3: =IFERROR(IF('Nodos y Métricas'!H4="","",'Nodos y Métricas'!H4),"") -> 47 | E3: =IFERROR(IF('Nodos y Métricas'!I4="","",'Nodos y Métricas'!I4),"") -> Alta | F3: =IFERROR(IF('Nodos y Métricas'!J4="","",'Nodos y Métricas'!J4),"") -> Prioridad Alta
A4: =IFERROR(IF('Nodos y Métricas'!A5="","",'Nodos y Métricas'!A5),"") -> M1-P2 | B4: =IFERROR(IF('Nodos y Métricas'!B5="","",'Nodos y Métricas'!B5),"") -> Aseguramiento de la Calidad (SIAC) | C4: =IFERROR(IF('Nodos y Métricas'!C5="","",'Nodos y Métricas'!C5),"") -> M1 | D4: =IFERROR(IF('Nodos y Métricas'!H5="","",'Nodos y Métricas'!H5),"") -> 27 | E4: =IFERROR(IF('Nodos y Métricas'!I5="","",'Nodos y Métricas'!I5),"") -> Media | F4: =IFERROR(IF('Nodos y Métricas'!J5="","",'Nodos y Métricas'!J5),"") -> Prioridad Media
A5: =IFERROR(IF('Nodos y Métricas'!A6="","",'Nodos y Métricas'!A6),"") -> M1-P3 | B5: =IFERROR(IF('Nodos y Métricas'!B6="","",'Nodos y Métricas'!B6),"") -> Tránsito Vital | C5: =IFERROR(IF('Nodos y Métricas'!C6="","",'Nodos y Métricas'!C6),"") -> M1 | D5: =IFERROR(IF('Nodos y Métricas'!H6="","",'Nodos y Métricas'!H6),"") -> 28 | E5: =IFERROR(IF('Nodos y Métricas'!I6="","",'Nodos y Métricas'!I6),"") -> Alta | F5: =IFERROR(IF('Nodos y Métricas'!J6="","",'Nodos y Métricas'!J6),"") -> Prioridad Alta
A6: =IFERROR(IF('Nodos y Métricas'!A7="","",'Nodos y Métricas'!A7),"") -> M1-P4 | B6: =IFERROR(IF('Nodos y Métricas'!B7="","",'Nodos y Métricas'!B7),"") -> Voces y Saberes | C6: =IFERROR(IF('Nodos y Métricas'!C7="","",'Nodos y Métricas'!C7),"") -> M1 | D6: =IFERROR(IF('Nodos y Métricas'!H7="","",'Nodos y Métricas'!H7),"") -> 27 | E6: =IFERROR(IF('Nodos y Métricas'!I7="","",'Nodos y Métricas'!I7),"") -> Media | F6: =IFERROR(IF('Nodos y Métricas'!J7="","",'Nodos y Métricas'!J7),"") -> Prioridad Media
A7: =IFERROR(IF('Nodos y Métricas'!A8="","",'Nodos y Métricas'!A8),"") -> M1-P5 | B7: =IFERROR(IF('Nodos y Métricas'!B8="","",'Nodos y Métricas'!B8),"") -> Trayectorias de Futuro | C7: =IFERROR(IF('Nodos y Métricas'!C8="","",'Nodos y Métricas'!C8),"") -> M1 | D7: =IFERROR(IF('Nodos y Métricas'!H8="","",'Nodos y Métricas'!H8),"") -> 14 | E7: =IFERROR(IF('Nodos y Métricas'!I8="","",'Nodos y Métricas'!I8),"") -> Baja | F7: =IFERROR(IF('Nodos y Métricas'!J8="","",'Nodos y Métricas'!J8),"") -> Prioridad Baja
A8: =IFERROR(IF('Nodos y Métricas'!A9="","",'Nodos y Métricas'!A9),"") -> M2-P1 | B8: =IFERROR(IF('Nodos y Métricas'!B9="","",'Nodos y Métricas'!B9),"") -> Redes del Conocimiento | C8: =IFERROR(IF('Nodos y Métricas'!C9="","",'Nodos y Métricas'!C9),"") -> M2 | D8: =IFERROR(IF('Nodos y Métricas'!H9="","",'Nodos y Métricas'!H9),"") -> 27 | E8: =IFERROR(IF('Nodos y Métricas'!I9="","",'Nodos y Métricas'!I9),"") -> Media | F8: =IFERROR(IF('Nodos y Métricas'!J9="","",'Nodos y Métricas'!J9),"") -> Prioridad Media
A9: =IFERROR(IF('Nodos y Métricas'!A10="","",'Nodos y Métricas'!A10),"") -> M2-P2 | B9: =IFERROR(IF('Nodos y Métricas'!B10="","",'Nodos y Métricas'!B10),"") -> Misiones Académicas y Científicas | C9: =IFERROR(IF('Nodos y Métricas'!C10="","",'Nodos y Métricas'!C10),"") -> M2 | D9: =IFERROR(IF('Nodos y Métricas'!H10="","",'Nodos y Métricas'!H10),"") -> 32 | E9: =IFERROR(IF('Nodos y Métricas'!I10="","",'Nodos y Métricas'!I10),"") -> Alta | F9: =IFERROR(IF('Nodos y Métricas'!J10="","",'Nodos y Métricas'!J10),"") -> Prioridad Alta
A10: =IFERROR(IF('Nodos y Métricas'!A11="","",'Nodos y Métricas'!A11),"") -> M2-P3 | B10: =IFERROR(IF('Nodos y Métricas'!B11="","",'Nodos y Métricas'!B11),"") -> Laboratorios Vivos de Innovación | C10: =IFERROR(IF('Nodos y Métricas'!C11="","",'Nodos y Métricas'!C11),"") -> M2 | D10: =IFERROR(IF('Nodos y Métricas'!H11="","",'Nodos y Métricas'!H11),"") -> 32 | E10: =IFERROR(IF('Nodos y Métricas'!I11="","",'Nodos y Métricas'!I11),"") -> Alta | F10: =IFERROR(IF('Nodos y Métricas'!J11="","",'Nodos y Métricas'!J11),"") -> Prioridad Alta
A11: =IFERROR(IF('Nodos y Métricas'!A12="","",'Nodos y Métricas'!A12),"") -> M3-P1 | B11: =IFERROR(IF('Nodos y Métricas'!B12="","",'Nodos y Métricas'!B12),"") -> Viabilidad Financiera | C11: =IFERROR(IF('Nodos y Métricas'!C12="","",'Nodos y Métricas'!C12),"") -> M3 | D11: =IFERROR(IF('Nodos y Métricas'!H12="","",'Nodos y Métricas'!H12),"") -> 31 | E11: =IFERROR(IF('Nodos y Métricas'!I12="","",'Nodos y Métricas'!I12),"") -> Alta | F11: =IFERROR(IF('Nodos y Métricas'!J12="","",'Nodos y Métricas'!J12),"") -> Prioridad Alta
A12: =IFERROR(IF('Nodos y Métricas'!A13="","",'Nodos y Métricas'!A13),"") -> M3-P2 | B12: =IFERROR(IF('Nodos y Métricas'!B13="","",'Nodos y Métricas'!B13),"") -> Autorregulación Institucional | C12: =IFERROR(IF('Nodos y Métricas'!C13="","",'Nodos y Métricas'!C13),"") -> M3 | D12: =IFERROR(IF('Nodos y Métricas'!H13="","",'Nodos y Métricas'!H13),"") -> 24 | E12: =IFERROR(IF('Nodos y Métricas'!I13="","",'Nodos y Métricas'!I13),"") -> Media | F12: =IFERROR(IF('Nodos y Métricas'!J13="","",'Nodos y Métricas'!J13),"") -> Prioridad Media
A13: =IFERROR(IF('Nodos y Métricas'!A14="","",'Nodos y Métricas'!A14),"") -> M3-P3 | B13: =IFERROR(IF('Nodos y Métricas'!B14="","",'Nodos y Métricas'!B14),"") -> Alianzas y Cooperación para la Sostenibilidad | C13: =IFERROR(IF('Nodos y Métricas'!C14="","",'Nodos y Métricas'!C14),"") -> M3 | D13: =IFERROR(IF('Nodos y Métricas'!H14="","",'Nodos y Métricas'!H14),"") -> 19 | E13: =IFERROR(IF('Nodos y Métricas'!I14="","",'Nodos y Métricas'!I14),"") -> Baja | F13: =IFERROR(IF('Nodos y Métricas'!J14="","",'Nodos y Métricas'!J14),"") -> Prioridad Baja
A14: =IFERROR(IF('Nodos y Métricas'!A15="","",'Nodos y Métricas'!A15),"") -> M4-P1 | B14: =IFERROR(IF('Nodos y Métricas'!B15="","",'Nodos y Métricas'!B15),"") -> Cuidado Colectivo | C14: =IFERROR(IF('Nodos y Métricas'!C15="","",'Nodos y Métricas'!C15),"") -> M4 | D14: =IFERROR(IF('Nodos y Métricas'!H15="","",'Nodos y Métricas'!H15),"") -> 16 | E14: =IFERROR(IF('Nodos y Métricas'!I15="","",'Nodos y Métricas'!I15),"") -> Baja | F14: =IFERROR(IF('Nodos y Métricas'!J15="","",'Nodos y Métricas'!J15),"") -> Prioridad Baja
... A19: =IFERROR(IF('Nodos y Métricas'!A20="","",'Nodos y Métricas'!A20),"") -> M5-P4 | B19: =IFERROR(IF('Nodos y Métricas'!B20="","",'Nodos y Métricas'!B20),"") -> Universidad Ágil | C19: =IFERROR(IF('Nodos y Métricas'!C20="","",'Nodos y Métricas'!C20),"") -> M5 | D19: =IFERROR(IF('Nodos y Métricas'!H20="","",'Nodos y Métricas'!H20),"") -> 29 | E19: =IFERROR(IF('Nodos y Métricas'!I20="","",'Nodos y Métricas'!I20),"") -> Media | F19: =IFERROR(IF('Nodos y Métricas'!J20="","",'Nodos y Métricas'!J20),"") -> Prioridad Media
A21: CONEXIONES — Relaciones estratégicas entre proyectos (fuente: Relaciones · buffer 300 filas)
A22: Proyecto_Origen | B22: Proyecto_Destino | C22: Tipo_Relacion | D22: Intensidad | E22: Puntaje
A23: =IFERROR(IF(ISERROR(FIND("-P",Relaciones!A4)),"",IF(Relaciones!A4="","",Relaciones!A4)),"") -> M1-P1 | B23: =IFERROR(IF(A23="","",IF(Relaciones!D4="","",Relaciones!D4)),"") -> M3-P1 | C23: =IFERROR(IF(A23="","",IF(Relaciones!G4="","",Relaciones!G4)),"") -> Habilitadora | D23: =IFERROR(IF(A23="","",IF(Relaciones!H4="","",Relaciones!H4)),"") -> Media | E23: =IFERROR(IF(A23="","",IF(Relaciones!I4="","",Relaciones!I4)),"") -> 3
A24: =IFERROR(IF(ISERROR(FIND("-P",Relaciones!A5)),"",IF(Relaciones!A5="","",Relaciones!A5)),"") -> M1-P1 | B24: =IFERROR(IF(A24="","",IF(Relaciones!D5="","",Relaciones!D5)),"") -> M1-P5 | C24: =IFERROR(IF(A24="","",IF(Relaciones!G5="","",Relaciones!G5)),"") -> Habilitadora | D24: =IFERROR(IF(A24="","",IF(Relaciones!H5="","",Relaciones!H5)),"") -> Alta | E24: =IFERROR(IF(A24="","",IF(Relaciones!I5="","",Relaciones!I5)),"") -> 5
A25: =IFERROR(IF(ISERROR(FIND("-P",Relaciones!A6)),"",IF(Relaciones!A6="","",Relaciones!A6)),"") -> M1-P1 | B25: =IFERROR(IF(A25="","",IF(Relaciones!D6="","",Relaciones!D6)),"") -> M1-P3 | C25: =IFERROR(IF(A25="","",IF(Relaciones!G6="","",Relaciones!G6)),"") -> Complementariedad | D25: =IFERROR(IF(A25="","",IF(Relaciones!H6="","",Relaciones!H6)),"") -> Alta | E25: =IFERROR(IF(A25="","",IF(Relaciones!I6="","",Relaciones!I6)),"") -> 5
A26: =IFERROR(IF(ISERROR(FIND("-P",Relaciones!A7)),"",IF(Relaciones!A7="","",Relaciones!A7)),"") -> M1-P1 | B26: =IFERROR(IF(A26="","",IF(Relaciones!D7="","",Relaciones!D7)),"") -> M5-P3 | C26: =IFERROR(IF(A26="","",IF(Relaciones!G7="","",Relaciones!G7)),"") -> Complementariedad | D26: =IFERROR(IF(A26="","",IF(Relaciones!H7="","",Relaciones!H7)),"") -> Alta | E26: =IFERROR(IF(A26="","",IF(Relaciones!I7="","",Relaciones!I7)),"") -> 5
A27: =IFERROR(IF(ISERROR(FIND("-P",Relaciones!A8)),"",IF(Relaciones!A8="","",Relaciones!A8)),"") -> M1-P1 | B27: =IFERROR(IF(A27="","",IF(Relaciones!D8="","",Relaciones!D8)),"") -> M2-P2 | C27: =IFERROR(IF(A27="","",IF(Relaciones!G8="","",Relaciones!G8)),"") -> Complementariedad | D27: =IFERROR(IF(A27="","",IF(Relaciones!H8="","",Relaciones!H8)),"") -> Media | E27: =IFERROR(IF(A27="","",IF(Relaciones!I8="","",Relaciones!I8)),"") -> 3
A28: =IFERROR(IF(ISERROR(FIND("-P",Relaciones!A9)),"",IF(Relaciones!A9="","",Relaciones!A9)),"") -> M1-P1 | B28: =IFERROR(IF(A28="","",IF(Relaciones!D9="","",Relaciones!D9)),"") -> M2-P3 | C28: =IFERROR(IF(A28="","",IF(Relaciones!G9="","",Relaciones!G9)),"") -> Complementariedad | D28: =IFERROR(IF(A28="","",IF(Relaciones!H9="","",Relaciones!H9)),"") -> Media | E28: =IFERROR(IF(A28="","",IF(Relaciones!I9="","",Relaciones!I9)),"") -> 3
A29: =IFERROR(IF(ISERROR(FIND("-P",Relaciones!A10)),"",IF(Relaciones!A10="","",Relaciones!A10)),"") -> M1-P2 | B29: =IFERROR(IF(A29="","",IF(Relaciones!D10="","",Relaciones!D10)),"") -> M1-P1 | C29: =IFERROR(IF(A29="","",IF(Relaciones!G10="","",Relaciones!G10)),"") -> Habilitadora | D29: =IFERROR(IF(A29="","",IF(Relaciones!H10="","",Relaciones!H10)),"") -> Alta | E29: =IFERROR(IF(A29="","",IF(Relaciones!I10="","",Relaciones!I10)),"") -> 5
A30: =IFERROR(IF(ISERROR(FIND("-P",Relaciones!A11)),"",IF(Relaciones!A11="","",Relaciones!A11)),"") -> M1-P2 | B30: =IFERROR(IF(A30="","",IF(Relaciones!D11="","",Relaciones!D11)),"") -> M1-P3 | C30: =IFERROR(IF(A30="","",IF(Relaciones!G11="","",Relaciones!G11)),"") -> Habilitadora | D30: =IFERROR(IF(A30="","",IF(Relaciones!H11="","",Relaciones!H11)),"") -> Media | E30: =IFERROR(IF(A30="","",IF(Relaciones!I11="","",Relaciones!I11)),"") -> 3
A31: =IFERROR(IF(ISERROR(FIND("-P",Relaciones!A12)),"",IF(Relaciones!A12="","",Relaciones!A12)),"") -> M1-P2 | B31: =IFERROR(IF(A31="","",IF(Relaciones!D12="","",Relaciones!D12)),"") -> M1-P4 | C31: =IFERROR(IF(A31="","",IF(Relaciones!G12="","",Relaciones!G12)),"") -> Habilitadora | D31: =IFERROR(IF(A31="","",IF(Relaciones!H12="","",Relaciones!H12)),"") -> Media | E31: =IFERROR(IF(A31="","",IF(Relaciones!I12="","",Relaciones!I12)),"") -> 3
A32: =IFERROR(IF(ISERROR(FIND("-P",Relaciones!A13)),"",IF(Relaciones!A13="","",Relaciones!A13)),"") -> M1-P2 | B32: =IFERROR(IF(A32="","",IF(Relaciones!D13="","",Relaciones!D13)),"") -> M3-P2 | C32: =IFERROR(IF(A32="","",IF(Relaciones!G13="","",Relaciones!G13)),"") -> Complementariedad | D32: =IFERROR(IF(A32="","",IF(Relaciones!H13="","",Relaciones!H13)),"") -> Alta | E32: =IFERROR(IF(A32="","",IF(Relaciones!I13="","",Relaciones!I13)),"") -> 5
A33: =IFERROR(IF(ISERROR(FIND("-P",Relaciones!A14)),"",IF(Relaciones!A14="","",Relaciones!A14)),"") -> M1-P3 | B33: =IFERROR(IF(A33="","",IF(Relaciones!D14="","",Relaciones!D14)),"") -> M4-P1 | C33: =IFERROR(IF(A33="","",IF(Relaciones!G14="","",Relaciones!G14)),"") -> Complementariedad | D33: =IFERROR(IF(A33="","",IF(Relaciones!H14="","",Relaciones!H14)),"") -> Media | E33: =IFERROR(IF(A33="","",IF(Relaciones!I14="","",Relaciones!I14)),"") -> 3
A34: =IFERROR(IF(ISERROR(FIND("-P",Relaciones!A15)),"",IF(Relaciones!A15="","",Relaciones!A15)),"") -> M1-P3 | B34: =IFERROR(IF(A34="","",IF(Relaciones!D15="","",Relaciones!D15)),"") -> M1-P5 | C34: =IFERROR(IF(A34="","",IF(Relaciones!G15="","",Relaciones!G15)),"") -> Complementariedad | D34: =IFERROR(IF(A34="","",IF(Relaciones!H15="","",Relaciones!H15)),"") -> Media | E34: =IFERROR(IF(A34="","",IF(Relaciones!I15="","",Relaciones!I15)),"") -> 3
... A85: =IFERROR(IF(ISERROR(FIND("-P",Relaciones!A66)),"",IF(Relaciones!A66="","",Relaciones!A66)),"") | B85: =IFERROR(IF(A85="","",IF(Relaciones!D66="","",Relaciones!D66)),"") | C85: =IFERROR(IF(A85="","",IF(Relaciones!G66="","",Relaciones!G66)),"") | D85: =IFERROR(IF(A85="","",IF(Relaciones!H66="","",Relaciones!H66)),"") | E85: =IFERROR(IF(A85="","",IF(Relaciones!I66="","",Relaciones!I66)),"")
A86: =IFERROR(IF(ISERROR(FIND("-P",#REF!)),"",IF(#REF!="","",#REF!)),"") | B86: =IFERROR(IF(A86="","",IF(#REF!="","",#REF!)),"") | C86: =IFERROR(IF(A86="","",IF(#REF!="","",#REF!)),"") | D86: =IFERROR(IF(A86="","",IF(#REF!="","",#REF!)),"") | E86: =IFERROR(IF(A86="","",IF(#REF!="","",#REF!)),"")
A87: =IFERROR(IF(ISERROR(FIND("-P",#REF!)),"",IF(#REF!="","",#REF!)),"") | B87: =IFERROR(IF(A87="","",IF(#REF!="","",#REF!)),"") | C87: =IFERROR(IF(A87="","",IF(#REF!="","",#REF!)),"") | D87: =IFERROR(IF(A87="","",IF(#REF!="","",#REF!)),"") | E87: =IFERROR(IF(A87="","",IF(#REF!="","",#REF!)),"")
A88: =IFERROR(IF(ISERROR(FIND("-P",Relaciones!A68)),"",IF(Relaciones!A68="","",Relaciones!A68)),"") | B88: =IFERROR(IF(A88="","",IF(Relaciones!D68="","",Relaciones!D68)),"") | C88: =IFERROR(IF(A88="","",IF(Relaciones!G68="","",Relaciones!G68)),"") | D88: =IFERROR(IF(A88="","",IF(Relaciones!H68="","",Relaciones!H68)),"") | E88: =IFERROR(IF(A88="","",IF(Relaciones!I68="","",Relaciones!I68)),"")
A89: =IFERROR(IF(ISERROR(FIND("-P",Relaciones!A69)),"",IF(Relaciones!A69="","",Relaciones!A69)),"") | B89: =IFERROR(IF(A89="","",IF(Relaciones!D69="","",Relaciones!D69)),"") | C89: =IFERROR(IF(A89="","",IF(Relaciones!G69="","",Relaciones!G69)),"") | D89: =IFERROR(IF(A89="","",IF(Relaciones!H69="","",Relaciones!H69)),"") | E89: =IFERROR(IF(A89="","",IF(Relaciones!I69="","",Relaciones!I69)),"")
A90: =IFERROR(IF(ISERROR(FIND("-P",Relaciones!A70)),"",IF(Relaciones!A70="","",Relaciones!A70)),"") | B90: =IFERROR(IF(A90="","",IF(Relaciones!D70="","",Relaciones!D70)),"") | C90: =IFERROR(IF(A90="","",IF(Relaciones!G70="","",Relaciones!G70)),"") | D90: =IFERROR(IF(A90="","",IF(Relaciones!H70="","",Relaciones!H70)),"") | E90: =IFERROR(IF(A90="","",IF(Relaciones!I70="","",Relaciones!I70)),"")
A91: =IFERROR(IF(ISERROR(FIND("-P",Relaciones!A71)),"",IF(Relaciones!A71="","",Relaciones!A71)),"") | B91: =IFERROR(IF(A91="","",IF(Relaciones!D71="","",Relaciones!D71)),"") | C91: =IFERROR(IF(A91="","",IF(Relaciones!G71="","",Relaciones!G71)),"") | D91: =IFERROR(IF(A91="","",IF(Relaciones!H71="","",Relaciones!H71)),"") | E91: =IFERROR(IF(A91="","",IF(Relaciones!I71="","",Relaciones!I71)),"")
A92: =IFERROR(IF(ISERROR(FIND("-P",Relaciones!A72)),"",IF(Relaciones!A72="","",Relaciones!A72)),"") | B92: =IFERROR(IF(A92="","",IF(Relaciones!D72="","",Relaciones!D72)),"") | C92: =IFERROR(IF(A92="","",IF(Relaciones!G72="","",Relaciones!G72)),"") | D92: =IFERROR(IF(A92="","",IF(Relaciones!H72="","",Relaciones!H72)),"") | E92: =IFERROR(IF(A92="","",IF(Relaciones!I72="","",Relaciones!I72)),"")
A93: =IFERROR(IF(ISERROR(FIND("-P",Relaciones!A73)),"",IF(Relaciones!A73="","",Relaciones!A73)),"") | B93: =IFERROR(IF(A93="","",IF(Relaciones!D73="","",Relaciones!D73)),"") | C93: =IFERROR(IF(A93="","",IF(Relaciones!G73="","",Relaciones!G73)),"") | D93: =IFERROR(IF(A93="","",IF(Relaciones!H73="","",Relaciones!H73)),"") | E93: =IFERROR(IF(A93="","",IF(Relaciones!I73="","",Relaciones!I73)),"")
A94: =IFERROR(IF(ISERROR(FIND("-P",Relaciones!A74)),"",IF(Relaciones!A74="","",Relaciones!A74)),"") | B94: =IFERROR(IF(A94="","",IF(Relaciones!D74="","",Relaciones!D74)),"") | C94: =IFERROR(IF(A94="","",IF(Relaciones!G74="","",Relaciones!G74)),"") | D94: =IFERROR(IF(A94="","",IF(Relaciones!H74="","",Relaciones!H74)),"") | E94: =IFERROR(IF(A94="","",IF(Relaciones!I74="","",Relaciones!I74)),"")
A95: =IFERROR(IF(ISERROR(FIND("-P",Relaciones!A75)),"",IF(Relaciones!A75="","",Relaciones!A75)),"") | B95: =IFERROR(IF(A95="","",IF(Relaciones!D75="","",Relaciones!D75)),"") | C95: =IFERROR(IF(A95="","",IF(Relaciones!G75="","",Relaciones!G75)),"") | D95: =IFERROR(IF(A95="","",IF(Relaciones!H75="","",Relaciones!H75)),"") | E95: =IFERROR(IF(A95="","",IF(Relaciones!I75="","",Relaciones!I75)),"")
...

Sheet Mapa 17×17
A1: Mapa de Interdependencias 17×17 — PDI 2026–2029
A2: Tipo: H = Habilitadora · C = Complementariedad · D = Dependencia · S = Solapamiento | Intensidad: A = Alta · M = Media | Celda vacía = Sin relación directa identificada
A3: Origen → Destino ↓ | B3: M1-P1 | C3: M1-P2 | D3: M1-P3 | E3: M1-P4 | F3: M1-P5 | G3: M2-P1 | H3: M2-P2 | I3: M2-P3 | J3: M3-P1 | K3: M3-P2 | L3: M3-P3 | M3: M4-P1 | N3: M4-P2 | O3: M5-P1 | P3: M5-P2 | Q3: M5-P3 | R3: M5-P4
A4: M1-P1 | B4: ● | D4: C-A | F4: H-A | H4: C-M | I4: C-M | J4: D-M | Q4: S-A
A5: M1-P2 | B5: H-A | C5: ● | D5: H-M | E5: H-M | K5: C-A
A6: M1-P3 | D6: ● | F6: C-M | M6: C-M
A7: M1-P4 | B7: H-A | E7: ● | G7: H-M | H7: H-M | I7: H-M | Q7: S-A
A8: M1-P5 | B8: C-M | D8: H-M | F8: ●
A9: M2-P1 | G9: ● | H9: H-A | I9: H-A | L9: C-M
A10: M2-P2 | H10: ● | I10: C-A | L10: C-A
A11: M2-P3 | H11: C-A | I11: ● | L11: C-A
A12: M3-P1 | B12: H-A | G12: H-M | H12: H-M | I12: H-M | J12: ● | O12: H-M | P12: H-A | Q12: H-M
A13: M3-P2 | C13: C-A | K13: ● | M13: H-M | N13: H-M | R13: H-A
A14: M3-P3 | G14: C-M | L14: ●
A15: M4-P1 | D15: H-A | M15: ● | N15: C-A
A16: M4-P2 | D16: H-M | N16: ● | R16: C-A
A17: M5-P1 | C17: H-M | D17: H-M | L17: H-M | O17: ● | P17: H-A | Q17: H-A
A18: M5-P2 | P18: ● | Q18: H-A
A19: M5-P3 | B19: H-A | E19: H-A | G19: H-A | H19: H-M | I19: H-M | Q19: ● | R19: H-A
A20: M5-P4 | C20: H-M | J20: H-M | K20: C-M | N20: H-A | R20: ●
A22: Valores calculados con 58 relaciones desde la hoja Relaciones. ✔ Mapa actualizado — si modifica Relaciones, ejecute la macro de refresco o actualice este mapa manualmente.
A26: M1-P3 | B26: Tránsito Vital [Propuesta Formativa Integral y de Calidad] | E26: M4-P1 | F26: Cuidado Colectivo [Cultura del Cuidado, la Ética y el Servicio]
A27: M1-P4 | B27: Voces y Saberes [Propuesta Formativa Integral y de Calidad] | E27: M4-P2 | F27: Cultura del Servicio [Cultura del Cuidado, la Ética y el Servicio]
A28: M1-P5 | B28: Trayectorias de Futuro [Propuesta Formativa Integral y de Calidad] | E28: M5-P1 | F28: Madurez Digital Institucional [Ecosistema Digital]
A29: M2-P1 | B29: Redes del Conocimiento [Redes Multidimensionales del Conocimiento] | E29: M5-P2 | F29: Infraestructura Tecnológica [Ecosistema Digital]
A30: M2-P2 | B30: Misiones Académicas y Científicas [Redes Multidimensionales del Conocimiento] | E30: M5-P3 | F30: Herramientas Digitales [Ecosistema Digital]
A31: M2-P3 | B31: Laboratorios Vivos de Innovación [Redes Multidimensionales del Conocimiento] | E31: M5-P4 | F31: Universidad Ágil [Ecosistema Digital]
A32: M3-P1 | B32: Viabilidad Financiera [Universidad Sostenible]

Sheet PBI_NODOS
A1: ID_Proyecto | B1: Proyecto | C1: Macroproyecto | D1: Puntaje_Total | E1: Nivel_Articulacion | F1: Prioridad_Gestion
A2: ='Nodos y Métricas'!A4 -> M1-P1 | B2: ='Nodos y Métricas'!B4 -> Travesías del Conocimiento | C2: ='Nodos y Métricas'!C4 -> M1 | D2: ='Nodos y Métricas'!H4 -> 47 | E2: ='Nodos y Métricas'!I4 -> Alta | F2: ='Nodos y Métricas'!J4 -> Prioridad Alta
A3: ='Nodos y Métricas'!A5 -> M1-P2 | B3: ='Nodos y Métricas'!B5 -> Aseguramiento de la Calidad (SIAC) | C3: ='Nodos y Métricas'!C5 -> M1 | D3: ='Nodos y Métricas'!H5 -> 27 | E3: ='Nodos y Métricas'!I5 -> Media | F3: ='Nodos y Métricas'!J5 -> Prioridad Media
A4: ='Nodos y Métricas'!A6 -> M1-P3 | B4: ='Nodos y Métricas'!B6 -> Tránsito Vital | C4: ='Nodos y Métricas'!C6 -> M1 | D4: ='Nodos y Métricas'!H6 -> 28 | E4: ='Nodos y Métricas'!I6 -> Alta | F4: ='Nodos y Métricas'!J6 -> Prioridad Alta
A5: ='Nodos y Métricas'!A7 -> M1-P4 | B5: ='Nodos y Métricas'!B7 -> Voces y Saberes | C5: ='Nodos y Métricas'!C7 -> M1 | D5: ='Nodos y Métricas'!H7 -> 27 | E5: ='Nodos y Métricas'!I7 -> Media | F5: ='Nodos y Métricas'!J7 -> Prioridad Media
A6: ='Nodos y Métricas'!A8 -> M1-P5 | B6: ='Nodos y Métricas'!B8 -> Trayectorias de Futuro | C6: ='Nodos y Métricas'!C8 -> M1 | D6: ='Nodos y Métricas'!H8 -> 14 | E6: ='Nodos y Métricas'!I8 -> Baja | F6: ='Nodos y Métricas'!J8 -> Prioridad Baja
A7: ='Nodos y Métricas'!A9 -> M2-P1 | B7: ='Nodos y Métricas'!B9 -> Redes del Conocimiento | C7: ='Nodos y Métricas'!C9 -> M2 | D7: ='Nodos y Métricas'!H9 -> 27 | E7: ='Nodos y Métricas'!I9 -> Media | F7: ='Nodos y Métricas'!J9 -> Prioridad Media
A8: ='Nodos y Métricas'!A10 -> M2-P2 | B8: ='Nodos y Métricas'!B10 -> Misiones Académicas y Científicas | C8: ='Nodos y Métricas'!C10 -> M2 | D8: ='Nodos y Métricas'!H10 -> 32 | E8: ='Nodos y Métricas'!I10 -> Alta | F8: ='Nodos y Métricas'!J10 -> Prioridad Alta
A9: ='Nodos y Métricas'!A11 -> M2-P3 | B9: ='Nodos y Métricas'!B11 -> Laboratorios Vivos de Innovación | C9: ='Nodos y Métricas'!C11 -> M2 | D9: ='Nodos y Métricas'!H11 -> 32 | E9: ='Nodos y Métricas'!I11 -> Alta | F9: ='Nodos y Métricas'!J11 -> Prioridad Alta
A10: ='Nodos y Métricas'!A12 -> M3-P1 | B10: ='Nodos y Métricas'!B12 -> Viabilidad Financiera | C10: ='Nodos y Métricas'!C12 -> M3 | D10: ='Nodos y Métricas'!H12 -> 31 | E10: ='Nodos y Métricas'!I12 -> Alta | F10: ='Nodos y Métricas'!J12 -> Prioridad Alta
A11: ='Nodos y Métricas'!A13 -> M3-P2 | B11: ='Nodos y Métricas'!B13 -> Autorregulación Institucional | C11: ='Nodos y Métricas'!C13 -> M3 | D11: ='Nodos y Métricas'!H13 -> 24 | E11: ='Nodos y Métricas'!I13 -> Media | F11: ='Nodos y Métricas'!J13 -> Prioridad Media
A12: ='Nodos y Métricas'!A14 -> M3-P3 | B12: ='Nodos y Métricas'!B14 -> Alianzas y Cooperación para la Sostenibilidad | C12: ='Nodos y Métricas'!C14 -> M3 | D12: ='Nodos y Métricas'!H14 -> 19 | E12: ='Nodos y Métricas'!I14 -> Baja | F12: ='Nodos y Métricas'!J14 -> Prioridad Baja
A13: ='Nodos y Métricas'!A15 -> M4-P1 | B13: ='Nodos y Métricas'!B15 -> Cuidado Colectivo | C13: ='Nodos y Métricas'!C15 -> M4 | D13: ='Nodos y Métricas'!H15 -> 16 | E13: ='Nodos y Métricas'!I15 -> Baja | F13: ='Nodos y Métricas'!J15 -> Prioridad Baja
... A18: ='Nodos y Métricas'!A20 -> M5-P4 | B18: ='Nodos y Métricas'!B20 -> Universidad Ágil | C18: ='Nodos y Métricas'!C20 -> M5 | D18: ='Nodos y Métricas'!H20 -> 29 | E18: ='Nodos y Métricas'!I20 -> Media | F18: ='Nodos y Métricas'!J20 -> Prioridad Media

Sheet PBI_CONEXIONES
A1: Proyecto_Origen | B1: Proyecto_Destino | C1: Tipo_Relacion | D1: Intensidad | E1: Puntaje
A2: =IFERROR(IF(ISERROR(FIND("-P",Relaciones!A4)),"",Relaciones!A4),"") -> M1-P1 | B2: =IFERROR(IF(A2="","",Relaciones!D4),"") -> M3-P1 | C2: =IFERROR(IF(A2="","",Relaciones!G4),"") -> Habilitadora | D2: =IFERROR(IF(A2="","",Relaciones!H4),"") -> Media | E2: =IFERROR(IF(A2="","",Relaciones!I4),"") -> 3
A3: =IFERROR(IF(ISERROR(FIND("-P",Relaciones!A5)),"",Relaciones!A5),"") -> M1-P1 | B3: =IFERROR(IF(A3="","",Relaciones!D5),"") -> M1-P5 | C3: =IFERROR(IF(A3="","",Relaciones!G5),"") -> Habilitadora | D3: =IFERROR(IF(A3="","",Relaciones!H5),"") -> Alta | E3: =IFERROR(IF(A3="","",Relaciones!I5),"") -> 5
A4: =IFERROR(IF(ISERROR(FIND("-P",Relaciones!A6)),"",Relaciones!A6),"") -> M1-P1 | B4: =IFERROR(IF(A4="","",Relaciones!D6),"") -> M1-P3 | C4: =IFERROR(IF(A4="","",Relaciones!G6),"") -> Complementariedad | D4: =IFERROR(IF(A4="","",Relaciones!H6),"") -> Alta | E4: =IFERROR(IF(A4="","",Relaciones!I6),"") -> 5
A5: =IFERROR(IF(ISERROR(FIND("-P",Relaciones!A7)),"",Relaciones!A7),"") -> M1-P1 | B5: =IFERROR(IF(A5="","",Relaciones!D7),"") -> M5-P3 | C5: =IFERROR(IF(A5="","",Relaciones!G7),"") -> Complementariedad | D5: =IFERROR(IF(A5="","",Relaciones!H7),"") -> Alta | E5: =IFERROR(IF(A5="","",Relaciones!I7),"") -> 5
A6: =IFERROR(IF(ISERROR(FIND("-P",Relaciones!A8)),"",Relaciones!A8),"") -> M1-P1 | B6: =IFERROR(IF(A6="","",Relaciones!D8),"") -> M2-P2 | C6: =IFERROR(IF(A6="","",Relaciones!G8),"") -> Complementariedad | D6: =IFERROR(IF(A6="","",Relaciones!H8),"") -> Media | E6: =IFERROR(IF(A6="","",Relaciones!I8),"") -> 3
A7: =IFERROR(IF(ISERROR(FIND("-P",Relaciones!A9)),"",Relaciones!A9),"") -> M1-P1 | B7: =IFERROR(IF(A7="","",Relaciones!D9),"") -> M2-P3 | C7: =IFERROR(IF(A7="","",Relaciones!G9),"") -> Complementariedad | D7: =IFERROR(IF(A7="","",Relaciones!H9),"") -> Media | E7: =IFERROR(IF(A7="","",Relaciones!I9),"") -> 3
A8: =IFERROR(IF(ISERROR(FIND("-P",Relaciones!A10)),"",Relaciones!A10),"") -> M1-P2 | B8: =IFERROR(IF(A8="","",Relaciones!D10),"") -> M1-P1 | C8: =IFERROR(IF(A8="","",Relaciones!G10),"") -> Habilitadora | D8: =IFERROR(IF(A8="","",Relaciones!H10),"") -> Alta | E8: =IFERROR(IF(A8="","",Relaciones!I10),"") -> 5
A9: =IFERROR(IF(ISERROR(FIND("-P",Relaciones!A11)),"",Relaciones!A11),"") -> M1-P2 | B9: =IFERROR(IF(A9="","",Relaciones!D11),"") -> M1-P3 | C9: =IFERROR(IF(A9="","",Relaciones!G11),"") -> Habilitadora | D9: =IFERROR(IF(A9="","",Relaciones!H11),"") -> Media | E9: =IFERROR(IF(A9="","",Relaciones!I11),"") -> 3
A10: =IFERROR(IF(ISERROR(FIND("-P",Relaciones!A12)),"",Relaciones!A12),"") -> M1-P2 | B10: =IFERROR(IF(A10="","",Relaciones!D12),"") -> M1-P4 | C10: =IFERROR(IF(A10="","",Relaciones!G12),"") -> Habilitadora | D10: =IFERROR(IF(A10="","",Relaciones!H12),"") -> Media | E10: =IFERROR(IF(A10="","",Relaciones!I12),"") -> 3
A11: =IFERROR(IF(ISERROR(FIND("-P",Relaciones!A13)),"",Relaciones!A13),"") -> M1-P2 | B11: =IFERROR(IF(A11="","",Relaciones!D13),"") -> M3-P2 | C11: =IFERROR(IF(A11="","",Relaciones!G13),"") -> Complementariedad | D11: =IFERROR(IF(A11="","",Relaciones!H13),"") -> Alta | E11: =IFERROR(IF(A11="","",Relaciones!I13),"") -> 5
A12: =IFERROR(IF(ISERROR(FIND("-P",Relaciones!A14)),"",Relaciones!A14),"") -> M1-P3 | B12: =IFERROR(IF(A12="","",Relaciones!D14),"") -> M4-P1 | C12: =IFERROR(IF(A12="","",Relaciones!G14),"") -> Complementariedad | D12: =IFERROR(IF(A12="","",Relaciones!H14),"") -> Media | E12: =IFERROR(IF(A12="","",Relaciones!I14),"") -> 3
A13: =IFERROR(IF(ISERROR(FIND("-P",Relaciones!A15)),"",Relaciones!A15),"") -> M1-P3 | B13: =IFERROR(IF(A13="","",Relaciones!D15),"") -> M1-P5 | C13: =IFERROR(IF(A13="","",Relaciones!G15),"") -> Complementariedad | D13: =IFERROR(IF(A13="","",Relaciones!H15),"") -> Media | E13: =IFERROR(IF(A13="","",Relaciones!I15),"") -> 3
... A64: =IFERROR(IF(ISERROR(FIND("-P",Relaciones!A66)),"",Relaciones!A66),"") | B64: =IFERROR(IF(A64="","",Relaciones!D66),"") | C64: =IFERROR(IF(A64="","",Relaciones!G66),"") | D64: =IFERROR(IF(A64="","",Relaciones!H66),"") | E64: =IFERROR(IF(A64="","",Relaciones!I66),"")
A65: =IFERROR(IF(ISERROR(FIND("-P",#REF!)),"",#REF!),"") | B65: =IFERROR(IF(A65="","",#REF!),"") | C65: =IFERROR(IF(A65="","",#REF!),"") | D65: =IFERROR(IF(A65="","",#REF!),"") | E65: =IFERROR(IF(A65="","",#REF!),"")
A66: =IFERROR(IF(ISERROR(FIND("-P",#REF!)),"",#REF!),"") | B66: =IFERROR(IF(A66="","",#REF!),"") | C66: =IFERROR(IF(A66="","",#REF!),"") | D66: =IFERROR(IF(A66="","",#REF!),"") | E66: =IFERROR(IF(A66="","",#REF!),"")
A67: =IFERROR(IF(ISERROR(FIND("-P",Relaciones!A68)),"",Relaciones!A68),"") | B67: =IFERROR(IF(A67="","",Relaciones!D68),"") | C67: =IFERROR(IF(A67="","",Relaciones!G68),"") | D67: =IFERROR(IF(A67="","",Relaciones!H68),"") | E67: =IFERROR(IF(A67="","",Relaciones!I68),"")
A68: =IFERROR(IF(ISERROR(FIND("-P",Relaciones!A69)),"",Relaciones!A69),"") | B68: =IFERROR(IF(A68="","",Relaciones!D69),"") | C68: =IFERROR(IF(A68="","",Relaciones!G69),"") | D68: =IFERROR(IF(A68="","",Relaciones!H69),"") | E68: =IFERROR(IF(A68="","",Relaciones!I69),"")
A69: =IFERROR(IF(ISERROR(FIND("-P",Relaciones!A70)),"",Relaciones!A70),"") | B69: =IFERROR(IF(A69="","",Relaciones!D70),"") | C69: =IFERROR(IF(A69="","",Relaciones!G70),"") | D69: =IFERROR(IF(A69="","",Relaciones!H70),"") | E69: =IFERROR(IF(A69="","",Relaciones!I70),"")
A70: =IFERROR(IF(ISERROR(FIND("-P",Relaciones!A71)),"",Relaciones!A71),"") | B70: =IFERROR(IF(A70="","",Relaciones!D71),"") | C70: =IFERROR(IF(A70="","",Relaciones!G71),"") | D70: =IFERROR(IF(A70="","",Relaciones!H71),"") | E70: =IFERROR(IF(A70="","",Relaciones!I71),"")
A71: =IFERROR(IF(ISERROR(FIND("-P",Relaciones!A72)),"",Relaciones!A72),"") | B71: =IFERROR(IF(A71="","",Relaciones!D72),"") | C71: =IFERROR(IF(A71="","",Relaciones!G72),"") | D71: =IFERROR(IF(A71="","",Relaciones!H72),"") | E71: =IFERROR(IF(A71="","",Relaciones!I72),"")
A72: =IFERROR(IF(ISERROR(FIND("-P",Relaciones!A73)),"",Relaciones!A73),"") | B72: =IFERROR(IF(A72="","",Relaciones!D73),"") | C72: =IFERROR(IF(A72="","",Relaciones!G73),"") | D72: =IFERROR(IF(A72="","",Relaciones!H73),"") | E72: =IFERROR(IF(A72="","",Relaciones!I73),"")
